Process A [NEW] (arrival time 102 ms) 85 CPU bursts
Process B [NEW] (arrival time 365 ms) 6 CPU bursts
Process C [NEW] (arrival time 246 ms) 95 CPU bursts
Process D [NEW] (arrival time 388 ms) 57 CPU bursts
Process E [NEW] (arrival time 1515 ms) 83 CPU bursts
Process F [NEW] (arrival time 1684 ms) 97 CPU bursts
Process G [NEW] (arrival time 669 ms) 1 CPU burst
Process H [NEW] (arrival time 376 ms) 49 CPU bursts
time 0ms: Simulator started for FCFS [Q <empty>]
time 102ms: Process A arrived; added to ready queue [Q A]
time 104ms: Process A started using the CPU for 1031ms burst [Q <empty>]
time 246ms: Process C arrived; added to ready queue [Q C]
time 365ms: Process B arrived; added to ready queue [Q C B]
time 376ms: Process H arrived; added to ready queue [Q C B H]
time 388ms: Process D arrived; added to ready queue [Q C B H D]
time 669ms: Process G arrived; added to ready queue [Q C B H D G]
time 1135ms: Process A completed a CPU burst; 84 bursts to go [Q C B H D G]
time 1135ms: Process A switching out of CPU; will block on I/O until time 1547ms [Q C B H D G]
time 1139ms: Process C started using the CPU for 3274ms burst [Q B H D G]
time 1515ms: Process E arrived; added to ready queue [Q B H D G E]
time 1547ms: Process A completed I/O; added to ready queue [Q B H D G E A]
time 1684ms: Process F arrived; added to ready queue [Q B H D G E A F]
time 4413ms: Process C completed a CPU burst; 94 bursts to go [Q B H D G E A F]
time 4413ms: Process C switching out of CPU; will block on I/O until time 4505ms [Q B H D G E A F]
time 4417ms: Process B started using the CPU for 848ms burst [Q H D G E A F]
time 4505ms: Process C completed I/O; added to ready queue [Q H D G E A F C]
time 5265ms: Process B completed a CPU burst; 5 bursts to go [Q H D G E A F C]
time 5265ms: Process B switching out of CPU; will block on I/O until time 6213ms [Q H D G E A F C]
time 5269ms: Process H started using the CPU for 340ms burst [Q D G E A F C]
time 5609ms: Process H completed a CPU burst; 48 bursts to go [Q D G E A F C]
time 5609ms: Process H switching out of CPU; will block on I/O until time 6227ms [Q D G E A F C]
time 5613ms: Process D started using the CPU for 722ms burst [Q G E A F C]
time 6213ms: Process B completed I/O; added to ready queue [Q G E A F C B]
time 6227ms: Process H completed I/O; added to ready queue [Q G E A F C B H]
time 6335ms: Process D completed a CPU burst; 56 bursts to go [Q G E A F C B H]
time 6335ms: Process D switching out of CPU; will block on I/O until time 7425ms [Q G E A F C B H]
time 6339ms: Process G started using the CPU for 543ms burst [Q E A F C B H]
time 6882ms: Process G terminated [Q E A F C B H]
time 6886ms: Process E started using the CPU for 391ms burst [Q A F C B H]
time 7277ms: Process E completed a CPU burst; 82 bursts to go [Q A F C B H]
time 7277ms: Process E switching out of CPU; will block on I/O until time 7840ms [Q A F C B H]
time 7281ms: Process A started using the CPU for 197ms burst [Q F C B H]
time 7425ms: Process D completed I/O; added to ready queue [Q F C B H D]
time 7478ms: Process A completed a CPU burst; 83 bursts to go [Q F C B H D]
time 7478ms: Process A switching out of CPU; will block on I/O until time 7979ms [Q F C B H D]
time 7482ms: Process F started using the CPU for 18ms burst [Q C B H D]
time 7500ms: Process F completed a CPU burst; 96 bursts to go [Q C B H D]
time 7500ms: Process F switching out of CPU; will block on I/O until time 9062ms [Q C B H D]
time 7504ms: Process C started using the CPU for 633ms burst [Q B H D]
time 7840ms: Process E completed I/O; added to ready queue [Q B H D E]
time 7979ms: Process A completed I/O; added to ready queue [Q B H D E A]
time 8137ms: Process C completed a CPU burst; 93 bursts to go [Q B H D E A]
time 8137ms: Process C switching out of CPU; will block on I/O until time 8183ms [Q B H D E A]
time 8141ms: Process B started using the CPU for 859ms burst [Q H D E A]
time 8183ms: Process C completed I/O; added to ready queue [Q H D E A C]
time 9000ms: Process B completed a CPU burst; 4 bursts to go [Q H D E A C]
time 9000ms: Process B switching out of CPU; will block on I/O until time 9674ms [Q H D E A C]
time 9004ms: Process H started using the CPU for 264ms burst [Q D E A C]
time 9062ms: Process F completed I/O; added to ready queue [Q D E A C F]
time 9268ms: Process H completed a CPU burst; 47 bursts to go [Q D E A C F]
time 9268ms: Process H switching out of CPU; will block on I/O until time 9407ms [Q D E A C F]
time 9272ms: Process D started using the CPU for 293ms burst [Q E A C F]
time 9407ms: Process H completed I/O; added to ready queue [Q E A C F H]
time 9565ms: Process D completed a CPU burst; 55 bursts to go [Q E A C F H]
time 9565ms: Process D switching out of CPU; will block on I/O until time 9880ms [Q E A C F H]
time 9569ms: Process E started using the CPU for 1198ms burst [Q A C F H]
time 9674ms: Process B completed I/O; added to ready queue [Q A C F H B]
time 9880ms: Process D completed I/O; added to ready queue [Q A C F H B D]
time 10767ms: Process E completed a CPU burst; 81 bursts to go [Q A C F H B D]
time 10767ms: Process E switching out of CPU; will block on I/O until time 13940ms [Q A C F H B D]
time 10771ms: Process A started using the CPU for 923ms burst [Q C F H B D]
time 11694ms: Process A completed a CPU burst; 82 bursts to go [Q C F H B D]
time 11694ms: Process A switching out of CPU; will block on I/O until time 13558ms [Q C F H B D]
time 11698ms: Process C started using the CPU for 512ms burst [Q F H B D]
time 12210ms: Process C completed a CPU burst; 92 bursts to go [Q F H B D]
time 12210ms: Process C switching out of CPU; will block on I/O until time 13804ms [Q F H B D]
time 12214ms: Process F started using the CPU for 1494ms burst [Q H B D]
time 13558ms: Process A completed I/O; added to ready queue [Q H B D A]
time 13708ms: Process F completed a CPU burst; 95 bursts to go [Q H B D A]
time 13708ms: Process F switching out of CPU; will block on I/O until time 13833ms [Q H B D A]
time 13712ms: Process H started using the CPU for 1555ms burst [Q B D A]
time 13804ms: Process C completed I/O; added to ready queue [Q B D A C]
time 13833ms: Process F completed I/O; added to ready queue [Q B D A C F]
time 13940ms: Process E completed I/O; added to ready queue [Q B D A C F E]
time 15267ms: Process H completed a CPU burst; 46 bursts to go [Q B D A C F E]
time 15267ms: Process H switching out of CPU; will block on I/O until time 15733ms [Q B D A C F E]
time 15271ms: Process B started using the CPU for 2199ms burst [Q D A C F E]
time 15733ms: Process H completed I/O; added to ready queue [Q D A C F E H]
time 17470ms: Process B completed a CPU burst; 3 bursts to go [Q D A C F E H]
time 17470ms: Process B switching out of CPU; will block on I/O until time 17859ms [Q D A C F E H]
time 17474ms: Process D started using the CPU for 375ms burst [Q A C F E H]
time 17849ms: Process D completed a CPU burst; 54 bursts to go [Q A C F E H]
time 17849ms: Process D switching out of CPU; will block on I/O until time 18678ms [Q A C F E H]
time 17853ms: Process A started using the CPU for 25ms burst [Q C F E H]
time 17859ms: Process B completed I/O; added to ready queue [Q C F E H B]
time 17878ms: Process A completed a CPU burst; 81 bursts to go [Q C F E H B]
time 17878ms: Process A switching out of CPU; will block on I/O until time 18573ms [Q C F E H B]
time 17882ms: Process C started using the CPU for 102ms burst [Q F E H B]
time 17984ms: Process C completed a CPU burst; 91 bursts to go [Q F E H B]
time 17984ms: Process C switching out of CPU; will block on I/O until time 18125ms [Q F E H B]
time 17988ms: Process F started using the CPU for 315ms burst [Q E H B]
time 18125ms: Process C completed I/O; added to ready queue [Q E H B C]
time 18303ms: Process F completed a CPU burst; 94 bursts to go [Q E H B C]
time 18303ms: Process F switching out of CPU; will block on I/O until time 18772ms [Q E H B C]
time 18307ms: Process E started using the CPU for 1339ms burst [Q H B C]
time 18573ms: Process A completed I/O; added to ready queue [Q H B C A]
time 18678ms: Process D completed I/O; added to ready queue [Q H B C A D]
time 18772ms: Process F completed I/O; added to ready queue [Q H B C A D F]
time 19646ms: Process E completed a CPU burst; 80 bursts to go [Q H B C A D F]
time 19646ms: Process E switching out of CPU; will block on I/O until time 20718ms [Q H B C A D F]
time 19650ms: Process H started using the CPU for 2705ms burst [Q B C A D F]
time 20718ms: Process E completed I/O; added to ready queue [Q B C A D F E]
time 22355ms: Process H completed a CPU burst; 45 bursts to go [Q B C A D F E]
time 22355ms: Process H switching out of CPU; will block on I/O until time 22758ms [Q B C A D F E]
time 22359ms: Process B started using the CPU for 21ms burst [Q C A D F E]
time 22380ms: Process B completed a CPU burst; 2 bursts to go [Q C A D F E]
time 22380ms: Process B switching out of CPU; will block on I/O until time 22569ms [Q C A D F E]
time 22384ms: Process C started using the CPU for 346ms burst [Q A D F E]
time 22569ms: Process B completed I/O; added to ready queue [Q A D F E B]
time 22730ms: Process C completed a CPU burst; 90 bursts to go [Q A D F E B]
time 22730ms: Process C switching out of CPU; will block on I/O until time 23759ms [Q A D F E B]
time 22734ms: Process A started using the CPU for 977ms burst [Q D F E B]
time 22758ms: Process H completed I/O; added to ready queue [Q D F E B H]
time 23711ms: Process A completed a CPU burst; 80 bursts to go [Q D F E B H]
time 23711ms: Process A switching out of CPU; will block on I/O until time 24607ms [Q D F E B H]
time 23715ms: Process D started using the CPU for 245ms burst [Q F E B H]
time 23759ms: Process C completed I/O; added to ready queue [Q F E B H C]
time 23960ms: Process D completed a CPU burst; 53 bursts to go [Q F E B H C]
time 23960ms: Process D switching out of CPU; will block on I/O until time 24266ms [Q F E B H C]
time 23964ms: Process F started using the CPU for 890ms burst [Q E B H C]
time 24266ms: Process D completed I/O; added to ready queue [Q E B H C D]
time 24607ms: Process A completed I/O; added to ready queue [Q E B H C D A]
time 24854ms: Process F completed a CPU burst; 93 bursts to go [Q E B H C D A]
time 24854ms: Process F switching out of CPU; will block on I/O until time 25238ms [Q E B H C D A]
time 24858ms: Process E started using the CPU for 136ms burst [Q B H C D A]
time 24994ms: Process E completed a CPU burst; 79 bursts to go [Q B H C D A]
time 24994ms: Process E switching out of CPU; will block on I/O until time 26161ms [Q B H C D A]
time 24998ms: Process B started using the CPU for 909ms burst [Q H C D A]
time 25238ms: Process F completed I/O; added to ready queue [Q H C D A F]
time 25907ms: Process B completed a CPU burst; 1 burst to go [Q H C D A F]
time 25907ms: Process B switching out of CPU; will block on I/O until time 28296ms [Q H C D A F]
time 25911ms: Process H started using the CPU for 1716ms burst [Q C D A F]
time 26161ms: Process E completed I/O; added to ready queue [Q C D A F E]
time 27627ms: Process H completed a CPU burst; 44 bursts to go [Q C D A F E]
time 27627ms: Process H switching out of CPU; will block on I/O until time 28074ms [Q C D A F E]
time 27631ms: Process C started using the CPU for 81ms burst [Q D A F E]
time 27712ms: Process C completed a CPU burst; 89 bursts to go [Q D A F E]
time 27712ms: Process C switching out of CPU; will block on I/O until time 28960ms [Q D A F E]
time 27716ms: Process D started using the CPU for 855ms burst [Q A F E]
time 28074ms: Process H completed I/O; added to ready queue [Q A F E H]
time 28296ms: Process B completed I/O; added to ready queue [Q A F E H B]
time 28571ms: Process D completed a CPU burst; 52 bursts to go [Q A F E H B]
time 28571ms: Process D switching out of CPU; will block on I/O until time 30913ms [Q A F E H B]
time 28575ms: Process A started using the CPU for 1095ms burst [Q F E H B]
time 28960ms: Process C completed I/O; added to ready queue [Q F E H B C]
time 29670ms: Process A completed a CPU burst; 79 bursts to go [Q F E H B C]
time 29670ms: Process A switching out of CPU; will block on I/O until time 30011ms [Q F E H B C]
time 29674ms: Process F started using the CPU for 3843ms burst [Q E H B C]
time 30011ms: Process A completed I/O; added to ready queue [Q E H B C A]
time 30913ms: Process D completed I/O; added to ready queue [Q E H B C A D]
time 33517ms: Process F completed a CPU burst; 92 bursts to go [Q E H B C A D]
time 33517ms: Process F switching out of CPU; will block on I/O until time 35609ms [Q E H B C A D]
time 33521ms: Process E started using the CPU for 2127ms burst [Q H B C A D]
time 35609ms: Process F completed I/O; added to ready queue [Q H B C A D F]
time 35648ms: Process E completed a CPU burst; 78 bursts to go [Q H B C A D F]
time 35648ms: Process E switching out of CPU; will block on I/O until time 36708ms [Q H B C A D F]
time 35652ms: Process H started using the CPU for 615ms burst [Q B C A D F]
time 36267ms: Process H completed a CPU burst; 43 bursts to go [Q B C A D F]
time 36267ms: Process H switching out of CPU; will block on I/O until time 36444ms [Q B C A D F]
time 36271ms: Process B started using the CPU for 70ms burst [Q C A D F]
time 36341ms: Process B terminated [Q C A D F]
time 36345ms: Process C started using the CPU for 1562ms burst [Q A D F]
time 36444ms: Process H completed I/O; added to ready queue [Q A D F H]
time 36708ms: Process E completed I/O; added to ready queue [Q A D F H E]
time 37907ms: Process C completed a CPU burst; 88 bursts to go [Q A D F H E]
time 37907ms: Process C switching out of CPU; will block on I/O until time 38398ms [Q A D F H E]
time 37911ms: Process A started using the CPU for 117ms burst [Q D F H E]
time 38028ms: Process A completed a CPU burst; 78 bursts to go [Q D F H E]
time 38028ms: Process A switching out of CPU; will block on I/O until time 39743ms [Q D F H E]
time 38032ms: Process D started using the CPU for 1730ms burst [Q F H E]
time 38398ms: Process C completed I/O; added to ready queue [Q F H E C]
time 39743ms: Process A completed I/O; added to ready queue [Q F H E C A]
time 39762ms: Process D completed a CPU burst; 51 bursts to go [Q F H E C A]
time 39762ms: Process D switching out of CPU; will block on I/O until time 40618ms [Q F H E C A]
time 39766ms: Process F started using the CPU for 2701ms burst [Q H E C A]
time 40618ms: Process D completed I/O; added to ready queue [Q H E C A D]
time 42467ms: Process F completed a CPU burst; 91 bursts to go [Q H E C A D]
time 42467ms: Process F switching out of CPU; will block on I/O until time 46080ms [Q H E C A D]
time 42471ms: Process H started using the CPU for 828ms burst [Q E C A D]
time 43299ms: Process H completed a CPU burst; 42 bursts to go [Q E C A D]
time 43299ms: Process H switching out of CPU; will block on I/O until time 45140ms [Q E C A D]
time 43303ms: Process E started using the CPU for 351ms burst [Q C A D]
time 43654ms: Process E completed a CPU burst; 77 bursts to go [Q C A D]
time 43654ms: Process E switching out of CPU; will block on I/O until time 43753ms [Q C A D]
time 43658ms: Process C started using the CPU for 280ms burst [Q A D]
time 43753ms: Process E completed I/O; added to ready queue [Q A D E]
time 43938ms: Process C completed a CPU burst; 87 bursts to go [Q A D E]
time 43938ms: Process C switching out of CPU; will block on I/O until time 43950ms [Q A D E]
time 43942ms: Process A started using the CPU for 533ms burst [Q D E]
time 43950ms: Process C completed I/O; added to ready queue [Q D E C]
time 44475ms: Process A completed a CPU burst; 77 bursts to go [Q D E C]
time 44475ms: Process A switching out of CPU; will block on I/O until time 45099ms [Q D E C]
time 44479ms: Process D started using the CPU for 601ms burst [Q E C]
time 45080ms: Process D completed a CPU burst; 50 bursts to go [Q E C]
time 45080ms: Process D switching out of CPU; will block on I/O until time 45318ms [Q E C]
time 45084ms: Process E started using the CPU for 2531ms burst [Q C]
time 45099ms: Process A completed I/O; added to ready queue [Q C A]
time 45140ms: Process H completed I/O; added to ready queue [Q C A H]
time 45318ms: Process D completed I/O; added to ready queue [Q C A H D]
time 46080ms: Process F completed I/O; added to ready queue [Q C A H D F]
time 47615ms: Process E completed a CPU burst; 76 bursts to go [Q C A H D F]
time 47615ms: Process E switching out of CPU; will block on I/O until time 48668ms [Q C A H D F]
time 47619ms: Process C started using the CPU for 348ms burst [Q A H D F]
time 47967ms: Process C completed a CPU burst; 86 bursts to go [Q A H D F]
time 47967ms: Process C switching out of CPU; will block on I/O until time 48925ms [Q A H D F]
time 47971ms: Process A started using the CPU for 274ms burst [Q H D F]
time 48245ms: Process A completed a CPU burst; 76 bursts to go [Q H D F]
time 48245ms: Process A switching out of CPU; will block on I/O until time 50604ms [Q H D F]
time 48249ms: Process H started using the CPU for 863ms burst [Q D F]
time 48668ms: Process E completed I/O; added to ready queue [Q D F E]
time 48925ms: Process C completed I/O; added to ready queue [Q D F E C]
time 49112ms: Process H completed a CPU burst; 41 bursts to go [Q D F E C]
time 49112ms: Process H switching out of CPU; will block on I/O until time 49781ms [Q D F E C]
time 49116ms: Process D started using the CPU for 2089ms burst [Q F E C]
time 49781ms: Process H completed I/O; added to ready queue [Q F E C H]
time 50604ms: Process A completed I/O; added to ready queue [Q F E C H A]
time 51205ms: Process D completed a CPU burst; 49 bursts to go [Q F E C H A]
time 51205ms: Process D switching out of CPU; will block on I/O until time 51429ms [Q F E C H A]
time 51209ms: Process F started using the CPU for 259ms burst [Q E C H A]
time 51429ms: Process D completed I/O; added to ready queue [Q E C H A D]
time 51468ms: Process F completed a CPU burst; 90 bursts to go [Q E C H A D]
time 51468ms: Process F switching out of CPU; will block on I/O until time 52234ms [Q E C H A D]
time 51472ms: Process E started using the CPU for 2079ms burst [Q C H A D]
time 52234ms: Process F completed I/O; added to ready queue [Q C H A D F]
time 53551ms: Process E completed a CPU burst; 75 bursts to go [Q C H A D F]
time 53551ms: Process E switching out of CPU; will block on I/O until time 54622ms [Q C H A D F]
time 53555ms: Process C started using the CPU for 849ms burst [Q H A D F]
time 54404ms: Process C completed a CPU burst; 85 bursts to go [Q H A D F]
time 54404ms: Process C switching out of CPU; will block on I/O until time 54419ms [Q H A D F]
time 54408ms: Process H started using the CPU for 64ms burst [Q A D F]
time 54419ms: Process C completed I/O; added to ready queue [Q A D F C]
time 54472ms: Process H completed a CPU burst; 40 bursts to go [Q A D F C]
time 54472ms: Process H switching out of CPU; will block on I/O until time 55173ms [Q A D F C]
time 54476ms: Process A started using the CPU for 562ms burst [Q D F C]
time 54622ms: Process E completed I/O; added to ready queue [Q D F C E]
time 55038ms: Process A completed a CPU burst; 75 bursts to go [Q D F C E]
time 55038ms: Process A switching out of CPU; will block on I/O until time 57677ms [Q D F C E]
time 55042ms: Process D started using the CPU for 432ms burst [Q F C E]
time 55173ms: Process H completed I/O; added to ready queue [Q F C E H]
time 55474ms: Process D completed a CPU burst; 48 bursts to go [Q F C E H]
time 55474ms: Process D switching out of CPU; will block on I/O until time 56519ms [Q F C E H]
time 55478ms: Process F started using the CPU for 588ms burst [Q C E H]
time 56066ms: Process F completed a CPU burst; 89 bursts to go [Q C E H]
time 56066ms: Process F switching out of CPU; will block on I/O until time 57141ms [Q C E H]
time 56070ms: Process C started using the CPU for 238ms burst [Q E H]
time 56308ms: Process C completed a CPU burst; 84 bursts to go [Q E H]
time 56308ms: Process C switching out of CPU; will block on I/O until time 56645ms [Q E H]
time 56312ms: Process E started using the CPU for 466ms burst [Q H]
time 56519ms: Process D completed I/O; added to ready queue [Q H D]
time 56645ms: Process C completed I/O; added to ready queue [Q H D C]
time 56778ms: Process E completed a CPU burst; 74 bursts to go [Q H D C]
time 56778ms: Process E switching out of CPU; will block on I/O until time 58080ms [Q H D C]
time 56782ms: Process H started using the CPU for 1329ms burst [Q D C]
time 57141ms: Process F completed I/O; added to ready queue [Q D C F]
time 57677ms: Process A completed I/O; added to ready queue [Q D C F A]
time 58080ms: Process E completed I/O; added to ready queue [Q D C F A E]
time 58111ms: Process H completed a CPU burst; 39 bursts to go [Q D C F A E]
time 58111ms: Process H switching out of CPU; will block on I/O until time 58554ms [Q D C F A E]
time 58115ms: Process D started using the CPU for 812ms burst [Q C F A E]
time 58554ms: Process H completed I/O; added to ready queue [Q C F A E H]
time 58927ms: Process D completed a CPU burst; 47 bursts to go [Q C F A E H]
time 58927ms: Process D switching out of CPU; will block on I/O until time 59325ms [Q C F A E H]
time 58931ms: Process C started using the CPU for 1698ms burst [Q F A E H]
time 59325ms: Process D completed I/O; added to ready queue [Q F A E H D]
time 60629ms: Process C completed a CPU burst; 83 bursts to go [Q F A E H D]
time 60629ms: Process C switching out of CPU; will block on I/O until time 61428ms [Q F A E H D]
time 60633ms: Process F started using the CPU for 1774ms burst [Q A E H D]
time 61428ms: Process C completed I/O; added to ready queue [Q A E H D C]
time 62407ms: Process F completed a CPU burst; 88 bursts to go [Q A E H D C]
time 62407ms: Process F switching out of CPU; will block on I/O until time 62446ms [Q A E H D C]
time 62411ms: Process A started using the CPU for 2553ms burst [Q E H D C]
time 62446ms: Process F completed I/O; added to ready queue [Q E H D C F]
time 64964ms: Process A completed a CPU burst; 74 bursts to go [Q E H D C F]
time 64964ms: Process A switching out of CPU; will block on I/O until time 65106ms [Q E H D C F]
time 64968ms: Process E started using the CPU for 564ms burst [Q H D C F]
time 65106ms: Process A completed I/O; added to ready queue [Q H D C F A]
time 65532ms: Process E completed a CPU burst; 73 bursts to go [Q H D C F A]
time 65532ms: Process E switching out of CPU; will block on I/O until time 67176ms [Q H D C F A]
time 65536ms: Process H started using the CPU for 2061ms burst [Q D C F A]
time 67176ms: Process E completed I/O; added to ready queue [Q D C F A E]
time 67597ms: Process H completed a CPU burst; 38 bursts to go [Q D C F A E]
time 67597ms: Process H switching out of CPU; will block on I/O until time 67940ms [Q D C F A E]
time 67601ms: Process D started using the CPU for 1501ms burst [Q C F A E]
time 67940ms: Process H completed I/O; added to ready queue [Q C F A E H]
time 69102ms: Process D completed a CPU burst; 46 bursts to go [Q C F A E H]
time 69102ms: Process D switching out of CPU; will block on I/O until time 70029ms [Q C F A E H]
time 69106ms: Process C started using the CPU for 1563ms burst [Q F A E H]
time 70029ms: Process D completed I/O; added to ready queue [Q F A E H D]
time 70669ms: Process C completed a CPU burst; 82 bursts to go [Q F A E H D]
time 70669ms: Process C switching out of CPU; will block on I/O until time 71009ms [Q F A E H D]
time 70673ms: Process F started using the CPU for 902ms burst [Q A E H D]
time 71009ms: Process C completed I/O; added to ready queue [Q A E H D C]
time 71575ms: Process F completed a CPU burst; 87 bursts to go [Q A E H D C]
time 71575ms: Process F switching out of CPU; will block on I/O until time 71867ms [Q A E H D C]
time 71579ms: Process A started using the CPU for 1023ms burst [Q E H D C]
time 71867ms: Process F completed I/O; added to ready queue [Q E H D C F]
time 72602ms: Process A completed a CPU burst; 73 bursts to go [Q E H D C F]
time 72602ms: Process A switching out of CPU; will block on I/O until time 73618ms [Q E H D C F]
time 72606ms: Process E started using the CPU for 1518ms burst [Q H D C F]
time 73618ms: Process A completed I/O; added to ready queue [Q H D C F A]
time 74124ms: Process E completed a CPU burst; 72 bursts to go [Q H D C F A]
time 74124ms: Process E switching out of CPU; will block on I/O until time 74790ms [Q H D C F A]
time 74128ms: Process H started using the CPU for 1088ms burst [Q D C F A]
time 74790ms: Process E completed I/O; added to ready queue [Q D C F A E]
time 75216ms: Process H completed a CPU burst; 37 bursts to go [Q D C F A E]
time 75216ms: Process H switching out of CPU; will block on I/O until time 75245ms [Q D C F A E]
time 75220ms: Process D started using the CPU for 1717ms burst [Q C F A E]
time 75245ms: Process H completed I/O; added to ready queue [Q C F A E H]
time 76937ms: Process D completed a CPU burst; 45 bursts to go [Q C F A E H]
time 76937ms: Process D switching out of CPU; will block on I/O until time 77121ms [Q C F A E H]
time 76941ms: Process C started using the CPU for 1428ms burst [Q F A E H]
time 77121ms: Process D completed I/O; added to ready queue [Q F A E H D]
time 78369ms: Process C completed a CPU burst; 81 bursts to go [Q F A E H D]
time 78369ms: Process C switching out of CPU; will block on I/O until time 80056ms [Q F A E H D]
time 78373ms: Process F started using the CPU for 806ms burst [Q A E H D]
time 79179ms: Process F completed a CPU burst; 86 bursts to go [Q A E H D]
time 79179ms: Process F switching out of CPU; will block on I/O until time 79410ms [Q A E H D]
time 79183ms: Process A started using the CPU for 319ms burst [Q E H D]
time 79410ms: Process F completed I/O; added to ready queue [Q E H D F]
time 79502ms: Process A completed a CPU burst; 72 bursts to go [Q E H D F]
time 79502ms: Process A switching out of CPU; will block on I/O until time 79742ms [Q E H D F]
time 79506ms: Process E started using the CPU for 740ms burst [Q H D F]
time 79742ms: Process A completed I/O; added to ready queue [Q H D F A]
time 80056ms: Process C completed I/O; added to ready queue [Q H D F A C]
time 80246ms: Process E completed a CPU burst; 71 bursts to go [Q H D F A C]
time 80246ms: Process E switching out of CPU; will block on I/O until time 80947ms [Q H D F A C]
time 80250ms: Process H started using the CPU for 92ms burst [Q D F A C]
time 80342ms: Process H completed a CPU burst; 36 bursts to go [Q D F A C]
time 80342ms: Process H switching out of CPU; will block on I/O until time 81724ms [Q D F A C]
time 80346ms: Process D started using the CPU for 1319ms burst [Q F A C]
time 80947ms: Process E completed I/O; added to ready queue [Q F A C E]
time 81665ms: Process D completed a CPU burst; 44 bursts to go [Q F A C E]
time 81665ms: Process D switching out of CPU; will block on I/O until time 82026ms [Q F A C E]
time 81669ms: Process F started using the CPU for 21ms burst [Q A C E]
time 81690ms: Process F completed a CPU burst; 85 bursts to go [Q A C E]
time 81690ms: Process F switching out of CPU; will block on I/O until time 82816ms [Q A C E]
time 81694ms: Process A started using the CPU for 1872ms burst [Q C E]
time 81724ms: Process H completed I/O; added to ready queue [Q C E H]
time 82026ms: Process D completed I/O; added to ready queue [Q C E H D]
time 82816ms: Process F completed I/O; added to ready queue [Q C E H D F]
time 83566ms: Process A completed a CPU burst; 71 bursts to go [Q C E H D F]
time 83566ms: Process A switching out of CPU; will block on I/O until time 84909ms [Q C E H D F]
time 83570ms: Process C started using the CPU for 1761ms burst [Q E H D F]
time 84909ms: Process A completed I/O; added to ready queue [Q E H D F A]
time 85331ms: Process C completed a CPU burst; 80 bursts to go [Q E H D F A]
time 85331ms: Process C switching out of CPU; will block on I/O until time 86110ms [Q E H D F A]
time 85335ms: Process E started using the CPU for 420ms burst [Q H D F A]
time 85755ms: Process E completed a CPU burst; 70 bursts to go [Q H D F A]
time 85755ms: Process E switching out of CPU; will block on I/O until time 86077ms [Q H D F A]
time 85759ms: Process H started using the CPU for 769ms burst [Q D F A]
time 86077ms: Process E completed I/O; added to ready queue [Q D F A E]
time 86110ms: Process C completed I/O; added to ready queue [Q D F A E C]
time 86528ms: Process H completed a CPU burst; 35 bursts to go [Q D F A E C]
time 86528ms: Process H switching out of CPU; will block on I/O until time 87522ms [Q D F A E C]
time 86532ms: Process D started using the CPU for 2816ms burst [Q F A E C]
time 87522ms: Process H completed I/O; added to ready queue [Q F A E C H]
time 89348ms: Process D completed a CPU burst; 43 bursts to go [Q F A E C H]
time 89348ms: Process D switching out of CPU; will block on I/O until time 90669ms [Q F A E C H]
time 89352ms: Process F started using the CPU for 1401ms burst [Q A E C H]
time 90669ms: Process D completed I/O; added to ready queue [Q A E C H D]
time 90753ms: Process F completed a CPU burst; 84 bursts to go [Q A E C H D]
time 90753ms: Process F switching out of CPU; will block on I/O until time 91786ms [Q A E C H D]
time 90757ms: Process A started using the CPU for 1788ms burst [Q E C H D]
time 91786ms: Process F completed I/O; added to ready queue [Q E C H D F]
time 92545ms: Process A completed a CPU burst; 70 bursts to go [Q E C H D F]
time 92545ms: Process A switching out of CPU; will block on I/O until time 92697ms [Q E C H D F]
time 92549ms: Process E started using the CPU for 1497ms burst [Q C H D F]
time 92697ms: Process A completed I/O; added to ready queue [Q C H D F A]
time 94046ms: Process E completed a CPU burst; 69 bursts to go [Q C H D F A]
time 94046ms: Process E switching out of CPU; will block on I/O until time 94539ms [Q C H D F A]
time 94050ms: Process C started using the CPU for 1852ms burst [Q H D F A]
time 94539ms: Process E completed I/O; added to ready queue [Q H D F A E]
time 95902ms: Process C completed a CPU burst; 79 bursts to go [Q H D F A E]
time 95902ms: Process C switching out of CPU; will block on I/O until time 96309ms [Q H D F A E]
time 95906ms: Process H started using the CPU for 2270ms burst [Q D F A E]
time 96309ms: Process C completed I/O; added to ready queue [Q D F A E C]
time 98176ms: Process H completed a CPU burst; 34 bursts to go [Q D F A E C]
time 98176ms: Process H switching out of CPU; will block on I/O until time 98666ms [Q D F A E C]
time 98180ms: Process D started using the CPU for 2717ms burst [Q F A E C]
time 98666ms: Process H completed I/O; added to ready queue [Q F A E C H]
time 100897ms: Process D completed a CPU burst; 42 bursts to go [Q F A E C H]
time 100897ms: Process D switching out of CPU; will block on I/O until time 101511ms [Q F A E C H]
time 100901ms: Process F started using the CPU for 215ms burst [Q A E C H]
time 101116ms: Process F completed a CPU burst; 83 bursts to go [Q A E C H]
time 101116ms: Process F switching out of CPU; will block on I/O until time 101317ms [Q A E C H]
time 101120ms: Process A started using the CPU for 313ms burst [Q E C H]
time 101317ms: Process F completed I/O; added to ready queue [Q E C H F]
time 101433ms: Process A completed a CPU burst; 69 bursts to go [Q E C H F]
time 101433ms: Process A switching out of CPU; will block on I/O until time 101516ms [Q E C H F]
time 101437ms: Process E started using the CPU for 985ms burst [Q C H F]
time 101511ms: Process D completed I/O; added to ready queue [Q C H F D]
time 101516ms: Process A completed I/O; added to ready queue [Q C H F D A]
time 102422ms: Process E completed a CPU burst; 68 bursts to go [Q C H F D A]
time 102422ms: Process E switching out of CPU; will block on I/O until time 102534ms [Q C H F D A]
time 102426ms: Process C started using the CPU for 230ms burst [Q H F D A]
time 102534ms: Process E completed I/O; added to ready queue [Q H F D A E]
time 102656ms: Process C completed a CPU burst; 78 bursts to go [Q H F D A E]
time 102656ms: Process C switching out of CPU; will block on I/O until time 103441ms [Q H F D A E]
time 102660ms: Process H started using the CPU for 2381ms burst [Q F D A E]
time 103441ms: Process C completed I/O; added to ready queue [Q F D A E C]
time 105041ms: Process H completed a CPU burst; 33 bursts to go [Q F D A E C]
time 105041ms: Process H switching out of CPU; will block on I/O until time 106523ms [Q F D A E C]
time 105045ms: Process F started using the CPU for 531ms burst [Q D A E C]
time 105576ms: Process F completed a CPU burst; 82 bursts to go [Q D A E C]
time 105576ms: Process F switching out of CPU; will block on I/O until time 106309ms [Q D A E C]
time 105580ms: Process D started using the CPU for 508ms burst [Q A E C]
time 106088ms: Process D completed a CPU burst; 41 bursts to go [Q A E C]
time 106088ms: Process D switching out of CPU; will block on I/O until time 107335ms [Q A E C]
time 106092ms: Process A started using the CPU for 1135ms burst [Q E C]
time 106309ms: Process F completed I/O; added to ready queue [Q E C F]
time 106523ms: Process H completed I/O; added to ready queue [Q E C F H]
time 107227ms: Process A completed a CPU burst; 68 bursts to go [Q E C F H]
time 107227ms: Process A switching out of CPU; will block on I/O until time 107379ms [Q E C F H]
time 107231ms: Process E started using the CPU for 1145ms burst [Q C F H]
time 107335ms: Process D completed I/O; added to ready queue [Q C F H D]
time 107379ms: Process A completed I/O; added to ready queue [Q C F H D A]
time 108376ms: Process E completed a CPU burst; 67 bursts to go [Q C F H D A]
time 108376ms: Process E switching out of CPU; will block on I/O until time 109313ms [Q C F H D A]
time 108380ms: Process C started using the CPU for 768ms burst [Q F H D A]
time 109148ms: Process C completed a CPU burst; 77 bursts to go [Q F H D A]
time 109148ms: Process C switching out of CPU; will block on I/O until time 109343ms [Q F H D A]
time 109152ms: Process F started using the CPU for 198ms burst [Q H D A]
time 109313ms: Process E completed I/O; added to ready queue [Q H D A E]
time 109343ms: Process C completed I/O; added to ready queue [Q H D A E C]
time 109350ms: Process F completed a CPU burst; 81 bursts to go [Q H D A E C]
time 109350ms: Process F switching out of CPU; will block on I/O until time 113017ms [Q H D A E C]
time 109354ms: Process H started using the CPU for 49ms burst [Q D A E C]
time 109403ms: Process H completed a CPU burst; 32 bursts to go [Q D A E C]
time 109403ms: Process H switching out of CPU; will block on I/O until time 109747ms [Q D A E C]
time 109407ms: Process D started using the CPU for 205ms burst [Q A E C]
time 109612ms: Process D completed a CPU burst; 40 bursts to go [Q A E C]
time 109612ms: Process D switching out of CPU; will block on I/O until time 110322ms [Q A E C]
time 109616ms: Process A started using the CPU for 1068ms burst [Q E C]
time 109747ms: Process H completed I/O; added to ready queue [Q E C H]
time 110322ms: Process D completed I/O; added to ready queue [Q E C H D]
time 110684ms: Process A completed a CPU burst; 67 bursts to go [Q E C H D]
time 110684ms: Process A switching out of CPU; will block on I/O until time 110763ms [Q E C H D]
time 110688ms: Process E started using the CPU for 593ms burst [Q C H D]
time 110763ms: Process A completed I/O; added to ready queue [Q C H D A]
time 111281ms: Process E completed a CPU burst; 66 bursts to go [Q C H D A]
time 111281ms: Process E switching out of CPU; will block on I/O until time 111829ms [Q C H D A]
time 111285ms: Process C started using the CPU for 106ms burst [Q H D A]
time 111391ms: Process C completed a CPU burst; 76 bursts to go [Q H D A]
time 111391ms: Process C switching out of CPU; will block on I/O until time 111962ms [Q H D A]
time 111395ms: Process H started using the CPU for 1969ms burst [Q D A]
time 111829ms: Process E completed I/O; added to ready queue [Q D A E]
time 111962ms: Process C completed I/O; added to ready queue [Q D A E C]
time 113017ms: Process F completed I/O; added to ready queue [Q D A E C F]
time 113364ms: Process H completed a CPU burst; 31 bursts to go [Q D A E C F]
time 113364ms: Process H switching out of CPU; will block on I/O until time 115046ms [Q D A E C F]
time 113368ms: Process D started using the CPU for 1404ms burst [Q A E C F]
time 114772ms: Process D completed a CPU burst; 39 bursts to go [Q A E C F]
time 114772ms: Process D switching out of CPU; will block on I/O until time 115963ms [Q A E C F]
time 114776ms: Process A started using the CPU for 447ms burst [Q E C F]
time 115046ms: Process H completed I/O; added to ready queue [Q E C F H]
time 115223ms: Process A completed a CPU burst; 66 bursts to go [Q E C F H]
time 115223ms: Process A switching out of CPU; will block on I/O until time 115274ms [Q E C F H]
time 115227ms: Process E started using the CPU for 1078ms burst [Q C F H]
time 115274ms: Process A completed I/O; added to ready queue [Q C F H A]
time 115963ms: Process D completed I/O; added to ready queue [Q C F H A D]
time 116305ms: Process E completed a CPU burst; 65 bursts to go [Q C F H A D]
time 116305ms: Process E switching out of CPU; will block on I/O until time 116704ms [Q C F H A D]
time 116309ms: Process C started using the CPU for 1544ms burst [Q F H A D]
time 116704ms: Process E completed I/O; added to ready queue [Q F H A D E]
time 117853ms: Process C completed a CPU burst; 75 bursts to go [Q F H A D E]
time 117853ms: Process C switching out of CPU; will block on I/O until time 119374ms [Q F H A D E]
time 117857ms: Process F started using the CPU for 218ms burst [Q H A D E]
time 118075ms: Process F completed a CPU burst; 80 bursts to go [Q H A D E]
time 118075ms: Process F switching out of CPU; will block on I/O until time 120085ms [Q H A D E]
time 118079ms: Process H started using the CPU for 622ms burst [Q A D E]
time 118701ms: Process H completed a CPU burst; 30 bursts to go [Q A D E]
time 118701ms: Process H switching out of CPU; will block on I/O until time 119703ms [Q A D E]
time 118705ms: Process A started using the CPU for 200ms burst [Q D E]
time 118905ms: Process A completed a CPU burst; 65 bursts to go [Q D E]
time 118905ms: Process A switching out of CPU; will block on I/O until time 120022ms [Q D E]
time 118909ms: Process D started using the CPU for 3202ms burst [Q E]
time 119374ms: Process C completed I/O; added to ready queue [Q E C]
time 119703ms: Process H completed I/O; added to ready queue [Q E C H]
time 120022ms: Process A completed I/O; added to ready queue [Q E C H A]
time 120085ms: Process F completed I/O; added to ready queue [Q E C H A F]
time 122111ms: Process D completed a CPU burst; 38 bursts to go [Q E C H A F]
time 122111ms: Process D switching out of CPU; will block on I/O until time 123413ms [Q E C H A F]
time 122115ms: Process E started using the CPU for 1045ms burst [Q C H A F]
time 123160ms: Process E completed a CPU burst; 64 bursts to go [Q C H A F]
time 123160ms: Process E switching out of CPU; will block on I/O until time 123802ms [Q C H A F]
time 123164ms: Process C started using the CPU for 147ms burst [Q H A F]
time 123311ms: Process C completed a CPU burst; 74 bursts to go [Q H A F]
time 123311ms: Process C switching out of CPU; will block on I/O until time 123432ms [Q H A F]
time 123315ms: Process H started using the CPU for 2420ms burst [Q A F]
time 123413ms: Process D completed I/O; added to ready queue [Q A F D]
time 123432ms: Process C completed I/O; added to ready queue [Q A F D C]
time 123802ms: Process E completed I/O; added to ready queue [Q A F D C E]
time 125735ms: Process H completed a CPU burst; 29 bursts to go [Q A F D C E]
time 125735ms: Process H switching out of CPU; will block on I/O until time 126186ms [Q A F D C E]
time 125739ms: Process A started using the CPU for 722ms burst [Q F D C E]
time 126186ms: Process H completed I/O; added to ready queue [Q F D C E H]
time 126461ms: Process A completed a CPU burst; 64 bursts to go [Q F D C E H]
time 126461ms: Process A switching out of CPU; will block on I/O until time 127268ms [Q F D C E H]
time 126465ms: Process F started using the CPU for 914ms burst [Q D C E H]
time 127268ms: Process A completed I/O; added to ready queue [Q D C E H A]
time 127379ms: Process F completed a CPU burst; 79 bursts to go [Q D C E H A]
time 127379ms: Process F switching out of CPU; will block on I/O until time 128944ms [Q D C E H A]
time 127383ms: Process D started using the CPU for 521ms burst [Q C E H A]
time 127904ms: Process D completed a CPU burst; 37 bursts to go [Q C E H A]
time 127904ms: Process D switching out of CPU; will block on I/O until time 130487ms [Q C E H A]
time 127908ms: Process C started using the CPU for 2148ms burst [Q E H A]
time 128944ms: Process F completed I/O; added to ready queue [Q E H A F]
time 130056ms: Process C completed a CPU burst; 73 bursts to go [Q E H A F]
time 130056ms: Process C switching out of CPU; will block on I/O until time 131600ms [Q E H A F]
time 130060ms: Process E started using the CPU for 910ms burst [Q H A F]
time 130487ms: Process D completed I/O; added to ready queue [Q H A F D]
time 130970ms: Process E completed a CPU burst; 63 bursts to go [Q H A F D]
time 130970ms: Process E switching out of CPU; will block on I/O until time 133919ms [Q H A F D]
time 130974ms: Process H started using the CPU for 1623ms burst [Q A F D]
time 131600ms: Process C completed I/O; added to ready queue [Q A F D C]
time 132597ms: Process H completed a CPU burst; 28 bursts to go [Q A F D C]
time 132597ms: Process H switching out of CPU; will block on I/O until time 132956ms [Q A F D C]
time 132601ms: Process A started using the CPU for 196ms burst [Q F D C]
time 132797ms: Process A completed a CPU burst; 63 bursts to go [Q F D C]
time 132797ms: Process A switching out of CPU; will block on I/O until time 133547ms [Q F D C]
time 132801ms: Process F started using the CPU for 1276ms burst [Q D C]
time 132956ms: Process H completed I/O; added to ready queue [Q D C H]
time 133547ms: Process A completed I/O; added to ready queue [Q D C H A]
time 133919ms: Process E completed I/O; added to ready queue [Q D C H A E]
time 134077ms: Process F completed a CPU burst; 78 bursts to go [Q D C H A E]
time 134077ms: Process F switching out of CPU; will block on I/O until time 134152ms [Q D C H A E]
time 134081ms: Process D started using the CPU for 713ms burst [Q C H A E]
time 134152ms: Process F completed I/O; added to ready queue [Q C H A E F]
time 134794ms: Process D completed a CPU burst; 36 bursts to go [Q C H A E F]
time 134794ms: Process D switching out of CPU; will block on I/O until time 136050ms [Q C H A E F]
time 134798ms: Process C started using the CPU for 1935ms burst [Q H A E F]
time 136050ms: Process D completed I/O; added to ready queue [Q H A E F D]
time 136733ms: Process C completed a CPU burst; 72 bursts to go [Q H A E F D]
time 136733ms: Process C switching out of CPU; will block on I/O until time 136872ms [Q H A E F D]
time 136737ms: Process H started using the CPU for 202ms burst [Q A E F D]
time 136872ms: Process C completed I/O; added to ready queue [Q A E F D C]
time 136939ms: Process H completed a CPU burst; 27 bursts to go [Q A E F D C]
time 136939ms: Process H switching out of CPU; will block on I/O until time 137902ms [Q A E F D C]
time 136943ms: Process A started using the CPU for 3198ms burst [Q E F D C]
time 137902ms: Process H completed I/O; added to ready queue [Q E F D C H]
time 140141ms: Process A completed a CPU burst; 62 bursts to go [Q E F D C H]
time 140141ms: Process A switching out of CPU; will block on I/O until time 142501ms [Q E F D C H]
time 140145ms: Process E started using the CPU for 2671ms burst [Q F D C H]
time 142501ms: Process A completed I/O; added to ready queue [Q F D C H A]
time 142816ms: Process E completed a CPU burst; 62 bursts to go [Q F D C H A]
time 142816ms: Process E switching out of CPU; will block on I/O until time 142847ms [Q F D C H A]
time 142820ms: Process F started using the CPU for 907ms burst [Q D C H A]
time 142847ms: Process E completed I/O; added to ready queue [Q D C H A E]
time 143727ms: Process F completed a CPU burst; 77 bursts to go [Q D C H A E]
time 143727ms: Process F switching out of CPU; will block on I/O until time 144135ms [Q D C H A E]
time 143731ms: Process D started using the CPU for 152ms burst [Q C H A E]
time 143883ms: Process D completed a CPU burst; 35 bursts to go [Q C H A E]
time 143883ms: Process D switching out of CPU; will block on I/O until time 144503ms [Q C H A E]
time 143887ms: Process C started using the CPU for 142ms burst [Q H A E]
time 144029ms: Process C completed a CPU burst; 71 bursts to go [Q H A E]
time 144029ms: Process C switching out of CPU; will block on I/O until time 145441ms [Q H A E]
time 144033ms: Process H started using the CPU for 244ms burst [Q A E]
time 144135ms: Process F completed I/O; added to ready queue [Q A E F]
time 144277ms: Process H completed a CPU burst; 26 bursts to go [Q A E F]
time 144277ms: Process H switching out of CPU; will block on I/O until time 145580ms [Q A E F]
time 144281ms: Process A started using the CPU for 687ms burst [Q E F]
time 144503ms: Process D completed I/O; added to ready queue [Q E F D]
time 144968ms: Process A completed a CPU burst; 61 bursts to go [Q E F D]
time 144968ms: Process A switching out of CPU; will block on I/O until time 145293ms [Q E F D]
time 144972ms: Process E started using the CPU for 734ms burst [Q F D]
time 145293ms: Process A completed I/O; added to ready queue [Q F D A]
time 145441ms: Process C completed I/O; added to ready queue [Q F D A C]
time 145580ms: Process H completed I/O; added to ready queue [Q F D A C H]
time 145706ms: Process E completed a CPU burst; 61 bursts to go [Q F D A C H]
time 145706ms: Process E switching out of CPU; will block on I/O until time 145849ms [Q F D A C H]
time 145710ms: Process F started using the CPU for 1623ms burst [Q D A C H]
time 145849ms: Process E completed I/O; added to ready queue [Q D A C H E]
time 147333ms: Process F completed a CPU burst; 76 bursts to go [Q D A C H E]
time 147333ms: Process F switching out of CPU; will block on I/O until time 150806ms [Q D A C H E]
time 147337ms: Process D started using the CPU for 666ms burst [Q A C H E]
time 148003ms: Process D completed a CPU burst; 34 bursts to go [Q A C H E]
time 148003ms: Process D switching out of CPU; will block on I/O until time 148740ms [Q A C H E]
time 148007ms: Process A started using the CPU for 1663ms burst [Q C H E]
time 148740ms: Process D completed I/O; added to ready queue [Q C H E D]
time 149670ms: Process A completed a CPU burst; 60 bursts to go [Q C H E D]
time 149670ms: Process A switching out of CPU; will block on I/O until time 150368ms [Q C H E D]
time 149674ms: Process C started using the CPU for 2295ms burst [Q H E D]
time 150368ms: Process A completed I/O; added to ready queue [Q H E D A]
time 150806ms: Process F completed I/O; added to ready queue [Q H E D A F]
time 151969ms: Process C completed a CPU burst; 70 bursts to go [Q H E D A F]
time 151969ms: Process C switching out of CPU; will block on I/O until time 152738ms [Q H E D A F]
time 151973ms: Process H started using the CPU for 45ms burst [Q E D A F]
time 152018ms: Process H completed a CPU burst; 25 bursts to go [Q E D A F]
time 152018ms: Process H switching out of CPU; will block on I/O until time 154415ms [Q E D A F]
time 152022ms: Process E started using the CPU for 215ms burst [Q D A F]
time 152237ms: Process E completed a CPU burst; 60 bursts to go [Q D A F]
time 152237ms: Process E switching out of CPU; will block on I/O until time 152850ms [Q D A F]
time 152241ms: Process D started using the CPU for 3886ms burst [Q A F]
time 152738ms: Process C completed I/O; added to ready queue [Q A F C]
time 152850ms: Process E completed I/O; added to ready queue [Q A F C E]
time 154415ms: Process H completed I/O; added to ready queue [Q A F C E H]
time 156127ms: Process D completed a CPU burst; 33 bursts to go [Q A F C E H]
time 156127ms: Process D switching out of CPU; will block on I/O until time 157112ms [Q A F C E H]
time 156131ms: Process A started using the CPU for 174ms burst [Q F C E H]
time 156305ms: Process A completed a CPU burst; 59 bursts to go [Q F C E H]
time 156305ms: Process A switching out of CPU; will block on I/O until time 156385ms [Q F C E H]
time 156309ms: Process F started using the CPU for 766ms burst [Q C E H]
time 156385ms: Process A completed I/O; added to ready queue [Q C E H A]
time 157075ms: Process F completed a CPU burst; 75 bursts to go [Q C E H A]
time 157075ms: Process F switching out of CPU; will block on I/O until time 157540ms [Q C E H A]
time 157079ms: Process C started using the CPU for 43ms burst [Q E H A]
time 157112ms: Process D completed I/O; added to ready queue [Q E H A D]
time 157122ms: Process C completed a CPU burst; 69 bursts to go [Q E H A D]
time 157122ms: Process C switching out of CPU; will block on I/O until time 158823ms [Q E H A D]
time 157126ms: Process E started using the CPU for 1141ms burst [Q H A D]
time 157540ms: Process F completed I/O; added to ready queue [Q H A D F]
time 158267ms: Process E completed a CPU burst; 59 bursts to go [Q H A D F]
time 158267ms: Process E switching out of CPU; will block on I/O until time 160232ms [Q H A D F]
time 158271ms: Process H started using the CPU for 1078ms burst [Q A D F]
time 158823ms: Process C completed I/O; added to ready queue [Q A D F C]
time 159349ms: Process H completed a CPU burst; 24 bursts to go [Q A D F C]
time 159349ms: Process H switching out of CPU; will block on I/O until time 160599ms [Q A D F C]
time 159353ms: Process A started using the CPU for 2151ms burst [Q D F C]
time 160232ms: Process E completed I/O; added to ready queue [Q D F C E]
time 160599ms: Process H completed I/O; added to ready queue [Q D F C E H]
time 161504ms: Process A completed a CPU burst; 58 bursts to go [Q D F C E H]
time 161504ms: Process A switching out of CPU; will block on I/O until time 161737ms [Q D F C E H]
time 161508ms: Process D started using the CPU for 1149ms burst [Q F C E H]
time 161737ms: Process A completed I/O; added to ready queue [Q F C E H A]
time 162657ms: Process D completed a CPU burst; 32 bursts to go [Q F C E H A]
time 162657ms: Process D switching out of CPU; will block on I/O until time 162819ms [Q F C E H A]
time 162661ms: Process F started using the CPU for 2644ms burst [Q C E H A]
time 162819ms: Process D completed I/O; added to ready queue [Q C E H A D]
time 165305ms: Process F completed a CPU burst; 74 bursts to go [Q C E H A D]
time 165305ms: Process F switching out of CPU; will block on I/O until time 165639ms [Q C E H A D]
time 165309ms: Process C started using the CPU for 1236ms burst [Q E H A D]
time 165639ms: Process F completed I/O; added to ready queue [Q E H A D F]
time 166545ms: Process C completed a CPU burst; 68 bursts to go [Q E H A D F]
time 166545ms: Process C switching out of CPU; will block on I/O until time 167754ms [Q E H A D F]
time 166549ms: Process E started using the CPU for 197ms burst [Q H A D F]
time 166746ms: Process E completed a CPU burst; 58 bursts to go [Q H A D F]
time 166746ms: Process E switching out of CPU; will block on I/O until time 170457ms [Q H A D F]
time 166750ms: Process H started using the CPU for 1191ms burst [Q A D F]
time 167754ms: Process C completed I/O; added to ready queue [Q A D F C]
time 167941ms: Process H completed a CPU burst; 23 bursts to go [Q A D F C]
time 167941ms: Process H switching out of CPU; will block on I/O until time 169756ms [Q A D F C]
time 167945ms: Process A started using the CPU for 322ms burst [Q D F C]
time 168267ms: Process A completed a CPU burst; 57 bursts to go [Q D F C]
time 168267ms: Process A switching out of CPU; will block on I/O until time 169248ms [Q D F C]
time 168271ms: Process D started using the CPU for 1085ms burst [Q F C]
time 169248ms: Process A completed I/O; added to ready queue [Q F C A]
time 169356ms: Process D completed a CPU burst; 31 bursts to go [Q F C A]
time 169356ms: Process D switching out of CPU; will block on I/O until time 170568ms [Q F C A]
time 169360ms: Process F started using the CPU for 79ms burst [Q C A]
time 169439ms: Process F completed a CPU burst; 73 bursts to go [Q C A]
time 169439ms: Process F switching out of CPU; will block on I/O until time 171339ms [Q C A]
time 169443ms: Process C started using the CPU for 41ms burst [Q A]
time 169484ms: Process C completed a CPU burst; 67 bursts to go [Q A]
time 169484ms: Process C switching out of CPU; will block on I/O until time 170779ms [Q A]
time 169488ms: Process A started using the CPU for 468ms burst [Q <empty>]
time 169756ms: Process H completed I/O; added to ready queue [Q H]
time 169956ms: Process A completed a CPU burst; 56 bursts to go [Q H]
time 169956ms: Process A switching out of CPU; will block on I/O until time 170242ms [Q H]
time 169960ms: Process H started using the CPU for 118ms burst [Q <empty>]
time 170078ms: Process H completed a CPU burst; 22 bursts to go [Q <empty>]
time 170078ms: Process H switching out of CPU; will block on I/O until time 170180ms [Q <empty>]
time 170180ms: Process H completed I/O; added to ready queue [Q H]
time 170182ms: Process H started using the CPU for 182ms burst [Q <empty>]
time 170242ms: Process A completed I/O; added to ready queue [Q A]
time 170364ms: Process H completed a CPU burst; 21 bursts to go [Q A]
time 170364ms: Process H switching out of CPU; will block on I/O until time 170760ms [Q A]
time 170368ms: Process A started using the CPU for 2475ms burst [Q <empty>]
time 170457ms: Process E completed I/O; added to ready queue [Q E]
time 170568ms: Process D completed I/O; added to ready queue [Q E D]
time 170760ms: Process H completed I/O; added to ready queue [Q E D H]
time 170779ms: Process C completed I/O; added to ready queue [Q E D H C]
time 171339ms: Process F completed I/O; added to ready queue [Q E D H C F]
time 172843ms: Process A completed a CPU burst; 55 bursts to go [Q E D H C F]
time 172843ms: Process A switching out of CPU; will block on I/O until time 172934ms [Q E D H C F]
time 172847ms: Process E started using the CPU for 708ms burst [Q D H C F]
time 172934ms: Process A completed I/O; added to ready queue [Q D H C F A]
time 173555ms: Process E completed a CPU burst; 57 bursts to go [Q D H C F A]
time 173555ms: Process E switching out of CPU; will block on I/O until time 174848ms [Q D H C F A]
time 173559ms: Process D started using the CPU for 1095ms burst [Q H C F A]
time 174654ms: Process D completed a CPU burst; 30 bursts to go [Q H C F A]
time 174654ms: Process D switching out of CPU; will block on I/O until time 176848ms [Q H C F A]
time 174658ms: Process H started using the CPU for 1827ms burst [Q C F A]
time 174848ms: Process E completed I/O; added to ready queue [Q C F A E]
time 176485ms: Process H completed a CPU burst; 20 bursts to go [Q C F A E]
time 176485ms: Process H switching out of CPU; will block on I/O until time 177033ms [Q C F A E]
time 176489ms: Process C started using the CPU for 626ms burst [Q F A E]
time 176848ms: Process D completed I/O; added to ready queue [Q F A E D]
time 177033ms: Process H completed I/O; added to ready queue [Q F A E D H]
time 177115ms: Process C completed a CPU burst; 66 bursts to go [Q F A E D H]
time 177115ms: Process C switching out of CPU; will block on I/O until time 178154ms [Q F A E D H]
time 177119ms: Process F started using the CPU for 23ms burst [Q A E D H]
time 177142ms: Process F completed a CPU burst; 72 bursts to go [Q A E D H]
time 177142ms: Process F switching out of CPU; will block on I/O until time 177528ms [Q A E D H]
time 177146ms: Process A started using the CPU for 639ms burst [Q E D H]
time 177528ms: Process F completed I/O; added to ready queue [Q E D H F]
time 177785ms: Process A completed a CPU burst; 54 bursts to go [Q E D H F]
time 177785ms: Process A switching out of CPU; will block on I/O until time 178429ms [Q E D H F]
time 177789ms: Process E started using the CPU for 691ms burst [Q D H F]
time 178154ms: Process C completed I/O; added to ready queue [Q D H F C]
time 178429ms: Process A completed I/O; added to ready queue [Q D H F C A]
time 178480ms: Process E completed a CPU burst; 56 bursts to go [Q D H F C A]
time 178480ms: Process E switching out of CPU; will block on I/O until time 179214ms [Q D H F C A]
time 178484ms: Process D started using the CPU for 24ms burst [Q H F C A]
time 178508ms: Process D completed a CPU burst; 29 bursts to go [Q H F C A]
time 178508ms: Process D switching out of CPU; will block on I/O until time 180520ms [Q H F C A]
time 178512ms: Process H started using the CPU for 2ms burst [Q F C A]
time 178514ms: Process H completed a CPU burst; 19 bursts to go [Q F C A]
time 178514ms: Process H switching out of CPU; will block on I/O until time 179809ms [Q F C A]
time 178518ms: Process F started using the CPU for 1130ms burst [Q C A]
time 179214ms: Process E completed I/O; added to ready queue [Q C A E]
time 179648ms: Process F completed a CPU burst; 71 bursts to go [Q C A E]
time 179648ms: Process F switching out of CPU; will block on I/O until time 180535ms [Q C A E]
time 179652ms: Process C started using the CPU for 378ms burst [Q A E]
time 179809ms: Process H completed I/O; added to ready queue [Q A E H]
time 180030ms: Process C completed a CPU burst; 65 bursts to go [Q A E H]
time 180030ms: Process C switching out of CPU; will block on I/O until time 180293ms [Q A E H]
time 180034ms: Process A started using the CPU for 2457ms burst [Q E H]
time 180293ms: Process C completed I/O; added to ready queue [Q E H C]
time 180520ms: Process D completed I/O; added to ready queue [Q E H C D]
time 180535ms: Process F completed I/O; added to ready queue [Q E H C D F]
time 182491ms: Process A completed a CPU burst; 53 bursts to go [Q E H C D F]
time 182491ms: Process A switching out of CPU; will block on I/O until time 185155ms [Q E H C D F]
time 182495ms: Process E started using the CPU for 98ms burst [Q H C D F]
time 182593ms: Process E completed a CPU burst; 55 bursts to go [Q H C D F]
time 182593ms: Process E switching out of CPU; will block on I/O until time 183904ms [Q H C D F]
time 182597ms: Process H started using the CPU for 398ms burst [Q C D F]
time 182995ms: Process H completed a CPU burst; 18 bursts to go [Q C D F]
time 182995ms: Process H switching out of CPU; will block on I/O until time 183906ms [Q C D F]
time 182999ms: Process C started using the CPU for 528ms burst [Q D F]
time 183527ms: Process C completed a CPU burst; 64 bursts to go [Q D F]
time 183527ms: Process C switching out of CPU; will block on I/O until time 184779ms [Q D F]
time 183531ms: Process D started using the CPU for 751ms burst [Q F]
time 183904ms: Process E completed I/O; added to ready queue [Q F E]
time 183906ms: Process H completed I/O; added to ready queue [Q F E H]
time 184282ms: Process D completed a CPU burst; 28 bursts to go [Q F E H]
time 184282ms: Process D switching out of CPU; will block on I/O until time 184728ms [Q F E H]
time 184286ms: Process F started using the CPU for 80ms burst [Q E H]
time 184366ms: Process F completed a CPU burst; 70 bursts to go [Q E H]
time 184366ms: Process F switching out of CPU; will block on I/O until time 185617ms [Q E H]
time 184370ms: Process E started using the CPU for 660ms burst [Q H]
time 184728ms: Process D completed I/O; added to ready queue [Q H D]
time 184779ms: Process C completed I/O; added to ready queue [Q H D C]
time 185030ms: Process E completed a CPU burst; 54 bursts to go [Q H D C]
time 185030ms: Process E switching out of CPU; will block on I/O until time 187393ms [Q H D C]
time 185034ms: Process H started using the CPU for 1096ms burst [Q D C]
time 185155ms: Process A completed I/O; added to ready queue [Q D C A]
time 185617ms: Process F completed I/O; added to ready queue [Q D C A F]
time 186130ms: Process H completed a CPU burst; 17 bursts to go [Q D C A F]
time 186130ms: Process H switching out of CPU; will block on I/O until time 189235ms [Q D C A F]
time 186134ms: Process D started using the CPU for 824ms burst [Q C A F]
time 186958ms: Process D completed a CPU burst; 27 bursts to go [Q C A F]
time 186958ms: Process D switching out of CPU; will block on I/O until time 186984ms [Q C A F]
time 186962ms: Process C started using the CPU for 3578ms burst [Q A F]
time 186984ms: Process D completed I/O; added to ready queue [Q A F D]
time 187393ms: Process E completed I/O; added to ready queue [Q A F D E]
time 189235ms: Process H completed I/O; added to ready queue [Q A F D E H]
time 190540ms: Process C completed a CPU burst; 63 bursts to go [Q A F D E H]
time 190540ms: Process C switching out of CPU; will block on I/O until time 190742ms [Q A F D E H]
time 190544ms: Process A started using the CPU for 184ms burst [Q F D E H]
time 190728ms: Process A completed a CPU burst; 52 bursts to go [Q F D E H]
time 190728ms: Process A switching out of CPU; will block on I/O until time 191478ms [Q F D E H]
time 190732ms: Process F started using the CPU for 239ms burst [Q D E H]
time 190742ms: Process C completed I/O; added to ready queue [Q D E H C]
time 190971ms: Process F completed a CPU burst; 69 bursts to go [Q D E H C]
time 190971ms: Process F switching out of CPU; will block on I/O until time 191021ms [Q D E H C]
time 190975ms: Process D started using the CPU for 135ms burst [Q E H C]
time 191021ms: Process F completed I/O; added to ready queue [Q E H C F]
time 191110ms: Process D completed a CPU burst; 26 bursts to go [Q E H C F]
time 191110ms: Process D switching out of CPU; will block on I/O until time 193551ms [Q E H C F]
time 191114ms: Process E started using the CPU for 445ms burst [Q H C F]
time 191478ms: Process A completed I/O; added to ready queue [Q H C F A]
time 191559ms: Process E completed a CPU burst; 53 bursts to go [Q H C F A]
time 191559ms: Process E switching out of CPU; will block on I/O until time 193397ms [Q H C F A]
time 191563ms: Process H started using the CPU for 286ms burst [Q C F A]
time 191849ms: Process H completed a CPU burst; 16 bursts to go [Q C F A]
time 191849ms: Process H switching out of CPU; will block on I/O until time 191990ms [Q C F A]
time 191853ms: Process C started using the CPU for 551ms burst [Q F A]
time 191990ms: Process H completed I/O; added to ready queue [Q F A H]
time 192404ms: Process C completed a CPU burst; 62 bursts to go [Q F A H]
time 192404ms: Process C switching out of CPU; will block on I/O until time 196279ms [Q F A H]
time 192408ms: Process F started using the CPU for 7ms burst [Q A H]
time 192415ms: Process F completed a CPU burst; 68 bursts to go [Q A H]
time 192415ms: Process F switching out of CPU; will block on I/O until time 192465ms [Q A H]
time 192419ms: Process A started using the CPU for 141ms burst [Q H]
time 192465ms: Process F completed I/O; added to ready queue [Q H F]
time 192560ms: Process A completed a CPU burst; 51 bursts to go [Q H F]
time 192560ms: Process A switching out of CPU; will block on I/O until time 192846ms [Q H F]
time 192564ms: Process H started using the CPU for 1908ms burst [Q F]
time 192846ms: Process A completed I/O; added to ready queue [Q F A]
time 193397ms: Process E completed I/O; added to ready queue [Q F A E]
time 193551ms: Process D completed I/O; added to ready queue [Q F A E D]
time 194472ms: Process H completed a CPU burst; 15 bursts to go [Q F A E D]
time 194472ms: Process H switching out of CPU; will block on I/O until time 196434ms [Q F A E D]
time 194476ms: Process F started using the CPU for 988ms burst [Q A E D]
time 195464ms: Process F completed a CPU burst; 67 bursts to go [Q A E D]
time 195464ms: Process F switching out of CPU; will block on I/O until time 195804ms [Q A E D]
time 195468ms: Process A started using the CPU for 2915ms burst [Q E D]
time 195804ms: Process F completed I/O; added to ready queue [Q E D F]
time 196279ms: Process C completed I/O; added to ready queue [Q E D F C]
time 196434ms: Process H completed I/O; added to ready queue [Q E D F C H]
time 198383ms: Process A completed a CPU burst; 50 bursts to go [Q E D F C H]
time 198383ms: Process A switching out of CPU; will block on I/O until time 198910ms [Q E D F C H]
time 198387ms: Process E started using the CPU for 458ms burst [Q D F C H]
time 198845ms: Process E completed a CPU burst; 52 bursts to go [Q D F C H]
time 198845ms: Process E switching out of CPU; will block on I/O until time 200406ms [Q D F C H]
time 198849ms: Process D started using the CPU for 760ms burst [Q F C H]
time 198910ms: Process A completed I/O; added to ready queue [Q F C H A]
time 199609ms: Process D completed a CPU burst; 25 bursts to go [Q F C H A]
time 199609ms: Process D switching out of CPU; will block on I/O until time 199636ms [Q F C H A]
time 199613ms: Process F started using the CPU for 700ms burst [Q C H A]
time 199636ms: Process D completed I/O; added to ready queue [Q C H A D]
time 200313ms: Process F completed a CPU burst; 66 bursts to go [Q C H A D]
time 200313ms: Process F switching out of CPU; will block on I/O until time 200500ms [Q C H A D]
time 200317ms: Process C started using the CPU for 34ms burst [Q H A D]
time 200351ms: Process C completed a CPU burst; 61 bursts to go [Q H A D]
time 200351ms: Process C switching out of CPU; will block on I/O until time 200429ms [Q H A D]
time 200355ms: Process H started using the CPU for 3276ms burst [Q A D]
time 200406ms: Process E completed I/O; added to ready queue [Q A D E]
time 200429ms: Process C completed I/O; added to ready queue [Q A D E C]
time 200500ms: Process F completed I/O; added to ready queue [Q A D E C F]
time 203631ms: Process H completed a CPU burst; 14 bursts to go [Q A D E C F]
time 203631ms: Process H switching out of CPU; will block on I/O until time 203887ms [Q A D E C F]
time 203635ms: Process A started using the CPU for 541ms burst [Q D E C F]
time 203887ms: Process H completed I/O; added to ready queue [Q D E C F H]
time 204176ms: Process A completed a CPU burst; 49 bursts to go [Q D E C F H]
time 204176ms: Process A switching out of CPU; will block on I/O until time 205671ms [Q D E C F H]
time 204180ms: Process D started using the CPU for 1466ms burst [Q E C F H]
time 205646ms: Process D completed a CPU burst; 24 bursts to go [Q E C F H]
time 205646ms: Process D switching out of CPU; will block on I/O until time 205704ms [Q E C F H]
time 205650ms: Process E started using the CPU for 170ms burst [Q C F H]
time 205671ms: Process A completed I/O; added to ready queue [Q C F H A]
time 205704ms: Process D completed I/O; added to ready queue [Q C F H A D]
time 205820ms: Process E completed a CPU burst; 51 bursts to go [Q C F H A D]
time 205820ms: Process E switching out of CPU; will block on I/O until time 206072ms [Q C F H A D]
time 205824ms: Process C started using the CPU for 2618ms burst [Q F H A D]
time 206072ms: Process E completed I/O; added to ready queue [Q F H A D E]
time 208442ms: Process C completed a CPU burst; 60 bursts to go [Q F H A D E]
time 208442ms: Process C switching out of CPU; will block on I/O until time 209291ms [Q F H A D E]
time 208446ms: Process F started using the CPU for 409ms burst [Q H A D E]
time 208855ms: Process F completed a CPU burst; 65 bursts to go [Q H A D E]
time 208855ms: Process F switching out of CPU; will block on I/O until time 209117ms [Q H A D E]
time 208859ms: Process H started using the CPU for 1008ms burst [Q A D E]
time 209117ms: Process F completed I/O; added to ready queue [Q A D E F]
time 209291ms: Process C completed I/O; added to ready queue [Q A D E F C]
time 209867ms: Process H completed a CPU burst; 13 bursts to go [Q A D E F C]
time 209867ms: Process H switching out of CPU; will block on I/O until time 209888ms [Q A D E F C]
time 209871ms: Process A started using the CPU for 65ms burst [Q D E F C]
time 209888ms: Process H completed I/O; added to ready queue [Q D E F C H]
time 209936ms: Process A completed a CPU burst; 48 bursts to go [Q D E F C H]
time 209936ms: Process A switching out of CPU; will block on I/O until time 211477ms [Q D E F C H]
time 209940ms: Process D started using the CPU for 1071ms burst [Q E F C H]
time 211011ms: Process D completed a CPU burst; 23 bursts to go [Q E F C H]
time 211011ms: Process D switching out of CPU; will block on I/O until time 212251ms [Q E F C H]
time 211015ms: Process E started using the CPU for 774ms burst [Q F C H]
time 211477ms: Process A completed I/O; added to ready queue [Q F C H A]
time 211789ms: Process E completed a CPU burst; 50 bursts to go [Q F C H A]
time 211789ms: Process E switching out of CPU; will block on I/O until time 213924ms [Q F C H A]
time 211793ms: Process F started using the CPU for 1355ms burst [Q C H A]
time 212251ms: Process D completed I/O; added to ready queue [Q C H A D]
time 213148ms: Process F completed a CPU burst; 64 bursts to go [Q C H A D]
time 213148ms: Process F switching out of CPU; will block on I/O until time 213663ms [Q C H A D]
time 213152ms: Process C started using the CPU for 805ms burst [Q H A D]
time 213663ms: Process F completed I/O; added to ready queue [Q H A D F]
time 213924ms: Process E completed I/O; added to ready queue [Q H A D F E]
time 213957ms: Process C completed a CPU burst; 59 bursts to go [Q H A D F E]
time 213957ms: Process C switching out of CPU; will block on I/O until time 215011ms [Q H A D F E]
time 213961ms: Process H started using the CPU for 3004ms burst [Q A D F E]
time 215011ms: Process C completed I/O; added to ready queue [Q A D F E C]
time 216965ms: Process H completed a CPU burst; 12 bursts to go [Q A D F E C]
time 216965ms: Process H switching out of CPU; will block on I/O until time 217155ms [Q A D F E C]
time 216969ms: Process A started using the CPU for 1213ms burst [Q D F E C]
time 217155ms: Process H completed I/O; added to ready queue [Q D F E C H]
time 218182ms: Process A completed a CPU burst; 47 bursts to go [Q D F E C H]
time 218182ms: Process A switching out of CPU; will block on I/O until time 219616ms [Q D F E C H]
time 218186ms: Process D started using the CPU for 75ms burst [Q F E C H]
time 218261ms: Process D completed a CPU burst; 22 bursts to go [Q F E C H]
time 218261ms: Process D switching out of CPU; will block on I/O until time 220669ms [Q F E C H]
time 218265ms: Process F started using the CPU for 196ms burst [Q E C H]
time 218461ms: Process F completed a CPU burst; 63 bursts to go [Q E C H]
time 218461ms: Process F switching out of CPU; will block on I/O until time 218658ms [Q E C H]
time 218465ms: Process E started using the CPU for 365ms burst [Q C H]
time 218658ms: Process F completed I/O; added to ready queue [Q C H F]
time 218830ms: Process E completed a CPU burst; 49 bursts to go [Q C H F]
time 218830ms: Process E switching out of CPU; will block on I/O until time 219816ms [Q C H F]
time 218834ms: Process C started using the CPU for 648ms burst [Q H F]
time 219482ms: Process C completed a CPU burst; 58 bursts to go [Q H F]
time 219482ms: Process C switching out of CPU; will block on I/O until time 219588ms [Q H F]
time 219486ms: Process H started using the CPU for 1207ms burst [Q F]
time 219588ms: Process C completed I/O; added to ready queue [Q F C]
time 219616ms: Process A completed I/O; added to ready queue [Q F C A]
time 219816ms: Process E completed I/O; added to ready queue [Q F C A E]
time 220669ms: Process D completed I/O; added to ready queue [Q F C A E D]
time 220693ms: Process H completed a CPU burst; 11 bursts to go [Q F C A E D]
time 220693ms: Process H switching out of CPU; will block on I/O until time 221785ms [Q F C A E D]
time 220697ms: Process F started using the CPU for 1736ms burst [Q C A E D]
time 221785ms: Process H completed I/O; added to ready queue [Q C A E D H]
time 222433ms: Process F completed a CPU burst; 62 bursts to go [Q C A E D H]
time 222433ms: Process F switching out of CPU; will block on I/O until time 223876ms [Q C A E D H]
time 222437ms: Process C started using the CPU for 837ms burst [Q A E D H]
time 223274ms: Process C completed a CPU burst; 57 bursts to go [Q A E D H]
time 223274ms: Process C switching out of CPU; will block on I/O until time 223851ms [Q A E D H]
time 223278ms: Process A started using the CPU for 676ms burst [Q E D H]
time 223851ms: Process C completed I/O; added to ready queue [Q E D H C]
time 223876ms: Process F completed I/O; added to ready queue [Q E D H C F]
time 223954ms: Process A completed a CPU burst; 46 bursts to go [Q E D H C F]
time 223954ms: Process A switching out of CPU; will block on I/O until time 224005ms [Q E D H C F]
time 223958ms: Process E started using the CPU for 16ms burst [Q D H C F]
time 223974ms: Process E completed a CPU burst; 48 bursts to go [Q D H C F]
time 223974ms: Process E switching out of CPU; will block on I/O until time 224186ms [Q D H C F]
time 223978ms: Process D started using the CPU for 492ms burst [Q H C F]
time 224005ms: Process A completed I/O; added to ready queue [Q H C F A]
time 224186ms: Process E completed I/O; added to ready queue [Q H C F A E]
time 224470ms: Process D completed a CPU burst; 21 bursts to go [Q H C F A E]
time 224470ms: Process D switching out of CPU; will block on I/O until time 226769ms [Q H C F A E]
time 224474ms: Process H started using the CPU for 424ms burst [Q C F A E]
time 224898ms: Process H completed a CPU burst; 10 bursts to go [Q C F A E]
time 224898ms: Process H switching out of CPU; will block on I/O until time 225255ms [Q C F A E]
time 224902ms: Process C started using the CPU for 115ms burst [Q F A E]
time 225017ms: Process C completed a CPU burst; 56 bursts to go [Q F A E]
time 225017ms: Process C switching out of CPU; will block on I/O until time 225197ms [Q F A E]
time 225021ms: Process F started using the CPU for 114ms burst [Q A E]
time 225135ms: Process F completed a CPU burst; 61 bursts to go [Q A E]
time 225135ms: Process F switching out of CPU; will block on I/O until time 226029ms [Q A E]
time 225139ms: Process A started using the CPU for 1128ms burst [Q E]
time 225197ms: Process C completed I/O; added to ready queue [Q E C]
time 225255ms: Process H completed I/O; added to ready queue [Q E C H]
time 226029ms: Process F completed I/O; added to ready queue [Q E C H F]
time 226267ms: Process A completed a CPU burst; 45 bursts to go [Q E C H F]
time 226267ms: Process A switching out of CPU; will block on I/O until time 226446ms [Q E C H F]
time 226271ms: Process E started using the CPU for 800ms burst [Q C H F]
time 226446ms: Process A completed I/O; added to ready queue [Q C H F A]
time 226769ms: Process D completed I/O; added to ready queue [Q C H F A D]
time 227071ms: Process E completed a CPU burst; 47 bursts to go [Q C H F A D]
time 227071ms: Process E switching out of CPU; will block on I/O until time 227721ms [Q C H F A D]
time 227075ms: Process C started using the CPU for 352ms burst [Q H F A D]
time 227427ms: Process C completed a CPU burst; 55 bursts to go [Q H F A D]
time 227427ms: Process C switching out of CPU; will block on I/O until time 227521ms [Q H F A D]
time 227431ms: Process H started using the CPU for 1359ms burst [Q F A D]
time 227521ms: Process C completed I/O; added to ready queue [Q F A D C]
time 227721ms: Process E completed I/O; added to ready queue [Q F A D C E]
time 228790ms: Process H completed a CPU burst; 9 bursts to go [Q F A D C E]
time 228790ms: Process H switching out of CPU; will block on I/O until time 229061ms [Q F A D C E]
time 228794ms: Process F started using the CPU for 577ms burst [Q A D C E]
time 229061ms: Process H completed I/O; added to ready queue [Q A D C E H]
time 229371ms: Process F completed a CPU burst; 60 bursts to go [Q A D C E H]
time 229371ms: Process F switching out of CPU; will block on I/O until time 230954ms [Q A D C E H]
time 229375ms: Process A started using the CPU for 229ms burst [Q D C E H]
time 229604ms: Process A completed a CPU burst; 44 bursts to go [Q D C E H]
time 229604ms: Process A switching out of CPU; will block on I/O until time 229618ms [Q D C E H]
time 229608ms: Process D started using the CPU for 22ms burst [Q C E H]
time 229618ms: Process A completed I/O; added to ready queue [Q C E H A]
time 229630ms: Process D completed a CPU burst; 20 bursts to go [Q C E H A]
time 229630ms: Process D switching out of CPU; will block on I/O until time 230464ms [Q C E H A]
time 229634ms: Process C started using the CPU for 2564ms burst [Q E H A]
time 230464ms: Process D completed I/O; added to ready queue [Q E H A D]
time 230954ms: Process F completed I/O; added to ready queue [Q E H A D F]
time 232198ms: Process C completed a CPU burst; 54 bursts to go [Q E H A D F]
time 232198ms: Process C switching out of CPU; will block on I/O until time 232242ms [Q E H A D F]
time 232202ms: Process E started using the CPU for 520ms burst [Q H A D F]
time 232242ms: Process C completed I/O; added to ready queue [Q H A D F C]
time 232722ms: Process E completed a CPU burst; 46 bursts to go [Q H A D F C]
time 232722ms: Process E switching out of CPU; will block on I/O until time 234240ms [Q H A D F C]
time 232726ms: Process H started using the CPU for 1357ms burst [Q A D F C]
time 234083ms: Process H completed a CPU burst; 8 bursts to go [Q A D F C]
time 234083ms: Process H switching out of CPU; will block on I/O until time 234143ms [Q A D F C]
time 234087ms: Process A started using the CPU for 390ms burst [Q D F C]
time 234143ms: Process H completed I/O; added to ready queue [Q D F C H]
time 234240ms: Process E completed I/O; added to ready queue [Q D F C H E]
time 234477ms: Process A completed a CPU burst; 43 bursts to go [Q D F C H E]
time 234477ms: Process A switching out of CPU; will block on I/O until time 236347ms [Q D F C H E]
time 234481ms: Process D started using the CPU for 435ms burst [Q F C H E]
time 234916ms: Process D completed a CPU burst; 19 bursts to go [Q F C H E]
time 234916ms: Process D switching out of CPU; will block on I/O until time 235015ms [Q F C H E]
time 234920ms: Process F started using the CPU for 986ms burst [Q C H E]
time 235015ms: Process D completed I/O; added to ready queue [Q C H E D]
time 235906ms: Process F completed a CPU burst; 59 bursts to go [Q C H E D]
time 235906ms: Process F switching out of CPU; will block on I/O until time 236947ms [Q C H E D]
time 235910ms: Process C started using the CPU for 1370ms burst [Q H E D]
time 236347ms: Process A completed I/O; added to ready queue [Q H E D A]
time 236947ms: Process F completed I/O; added to ready queue [Q H E D A F]
time 237280ms: Process C completed a CPU burst; 53 bursts to go [Q H E D A F]
time 237280ms: Process C switching out of CPU; will block on I/O until time 237347ms [Q H E D A F]
time 237284ms: Process H started using the CPU for 144ms burst [Q E D A F]
time 237347ms: Process C completed I/O; added to ready queue [Q E D A F C]
time 237428ms: Process H completed a CPU burst; 7 bursts to go [Q E D A F C]
time 237428ms: Process H switching out of CPU; will block on I/O until time 237512ms [Q E D A F C]
time 237432ms: Process E started using the CPU for 284ms burst [Q D A F C]
time 237512ms: Process H completed I/O; added to ready queue [Q D A F C H]
time 237716ms: Process E completed a CPU burst; 45 bursts to go [Q D A F C H]
time 237716ms: Process E switching out of CPU; will block on I/O until time 237976ms [Q D A F C H]
time 237720ms: Process D started using the CPU for 2552ms burst [Q A F C H]
time 237976ms: Process E completed I/O; added to ready queue [Q A F C H E]
time 240272ms: Process D completed a CPU burst; 18 bursts to go [Q A F C H E]
time 240272ms: Process D switching out of CPU; will block on I/O until time 240844ms [Q A F C H E]
time 240276ms: Process A started using the CPU for 905ms burst [Q F C H E]
time 240844ms: Process D completed I/O; added to ready queue [Q F C H E D]
time 241181ms: Process A completed a CPU burst; 42 bursts to go [Q F C H E D]
time 241181ms: Process A switching out of CPU; will block on I/O until time 241569ms [Q F C H E D]
time 241185ms: Process F started using the CPU for 37ms burst [Q C H E D]
time 241222ms: Process F completed a CPU burst; 58 bursts to go [Q C H E D]
time 241222ms: Process F switching out of CPU; will block on I/O until time 241974ms [Q C H E D]
time 241226ms: Process C started using the CPU for 204ms burst [Q H E D]
time 241430ms: Process C completed a CPU burst; 52 bursts to go [Q H E D]
time 241430ms: Process C switching out of CPU; will block on I/O until time 241863ms [Q H E D]
time 241434ms: Process H started using the CPU for 2541ms burst [Q E D]
time 241569ms: Process A completed I/O; added to ready queue [Q E D A]
time 241863ms: Process C completed I/O; added to ready queue [Q E D A C]
time 241974ms: Process F completed I/O; added to ready queue [Q E D A C F]
time 243975ms: Process H completed a CPU burst; 6 bursts to go [Q E D A C F]
time 243975ms: Process H switching out of CPU; will block on I/O until time 244832ms [Q E D A C F]
time 243979ms: Process E started using the CPU for 2021ms burst [Q D A C F]
time 244832ms: Process H completed I/O; added to ready queue [Q D A C F H]
time 246000ms: Process E completed a CPU burst; 44 bursts to go [Q D A C F H]
time 246000ms: Process E switching out of CPU; will block on I/O until time 249115ms [Q D A C F H]
time 246004ms: Process D started using the CPU for 851ms burst [Q A C F H]
time 246855ms: Process D completed a CPU burst; 17 bursts to go [Q A C F H]
time 246855ms: Process D switching out of CPU; will block on I/O until time 247167ms [Q A C F H]
time 246859ms: Process A started using the CPU for 118ms burst [Q C F H]
time 246977ms: Process A completed a CPU burst; 41 bursts to go [Q C F H]
time 246977ms: Process A switching out of CPU; will block on I/O until time 247045ms [Q C F H]
time 246981ms: Process C started using the CPU for 190ms burst [Q F H]
time 247045ms: Process A completed I/O; added to ready queue [Q F H A]
time 247167ms: Process D completed I/O; added to ready queue [Q F H A D]
time 247171ms: Process C completed a CPU burst; 51 bursts to go [Q F H A D]
time 247171ms: Process C switching out of CPU; will block on I/O until time 247674ms [Q F H A D]
time 247175ms: Process F started using the CPU for 174ms burst [Q H A D]
time 247349ms: Process F completed a CPU burst; 57 bursts to go [Q H A D]
time 247349ms: Process F switching out of CPU; will block on I/O until time 247869ms [Q H A D]
time 247353ms: Process H started using the CPU for 6ms burst [Q A D]
time 247359ms: Process H completed a CPU burst; 5 bursts to go [Q A D]
time 247359ms: Process H switching out of CPU; will block on I/O until time 247976ms [Q A D]
time 247363ms: Process A started using the CPU for 179ms burst [Q D]
time 247542ms: Process A completed a CPU burst; 40 bursts to go [Q D]
time 247542ms: Process A switching out of CPU; will block on I/O until time 249734ms [Q D]
time 247546ms: Process D started using the CPU for 742ms burst [Q <empty>]
time 247674ms: Process C completed I/O; added to ready queue [Q C]
time 247869ms: Process F completed I/O; added to ready queue [Q C F]
time 247976ms: Process H completed I/O; added to ready queue [Q C F H]
time 248288ms: Process D completed a CPU burst; 16 bursts to go [Q C F H]
time 248288ms: Process D switching out of CPU; will block on I/O until time 248544ms [Q C F H]
time 248292ms: Process C started using the CPU for 306ms burst [Q F H]
time 248544ms: Process D completed I/O; added to ready queue [Q F H D]
time 248598ms: Process C completed a CPU burst; 50 bursts to go [Q F H D]
time 248598ms: Process C switching out of CPU; will block on I/O until time 250069ms [Q F H D]
time 248602ms: Process F started using the CPU for 77ms burst [Q H D]
time 248679ms: Process F completed a CPU burst; 56 bursts to go [Q H D]
time 248679ms: Process F switching out of CPU; will block on I/O until time 250767ms [Q H D]
time 248683ms: Process H started using the CPU for 44ms burst [Q D]
time 248727ms: Process H completed a CPU burst; 4 bursts to go [Q D]
time 248727ms: Process H switching out of CPU; will block on I/O until time 249305ms [Q D]
time 248731ms: Process D started using the CPU for 2764ms burst [Q <empty>]
time 249115ms: Process E completed I/O; added to ready queue [Q E]
time 249305ms: Process H completed I/O; added to ready queue [Q E H]
time 249734ms: Process A completed I/O; added to ready queue [Q E H A]
time 250069ms: Process C completed I/O; added to ready queue [Q E H A C]
time 250767ms: Process F completed I/O; added to ready queue [Q E H A C F]
time 251495ms: Process D completed a CPU burst; 15 bursts to go [Q E H A C F]
time 251495ms: Process D switching out of CPU; will block on I/O until time 253042ms [Q E H A C F]
time 251499ms: Process E started using the CPU for 329ms burst [Q H A C F]
time 251828ms: Process E completed a CPU burst; 43 bursts to go [Q H A C F]
time 251828ms: Process E switching out of CPU; will block on I/O until time 252019ms [Q H A C F]
time 251832ms: Process H started using the CPU for 30ms burst [Q A C F]
time 251862ms: Process H completed a CPU burst; 3 bursts to go [Q A C F]
time 251862ms: Process H switching out of CPU; will block on I/O until time 252112ms [Q A C F]
time 251866ms: Process A started using the CPU for 513ms burst [Q C F]
time 252019ms: Process E completed I/O; added to ready queue [Q C F E]
time 252112ms: Process H completed I/O; added to ready queue [Q C F E H]
time 252379ms: Process A completed a CPU burst; 39 bursts to go [Q C F E H]
time 252379ms: Process A switching out of CPU; will block on I/O until time 252694ms [Q C F E H]
time 252383ms: Process C started using the CPU for 7ms burst [Q F E H]
time 252390ms: Process C completed a CPU burst; 49 bursts to go [Q F E H]
time 252390ms: Process C switching out of CPU; will block on I/O until time 252452ms [Q F E H]
time 252394ms: Process F started using the CPU for 2081ms burst [Q E H]
time 252452ms: Process C completed I/O; added to ready queue [Q E H C]
time 252694ms: Process A completed I/O; added to ready queue [Q E H C A]
time 253042ms: Process D completed I/O; added to ready queue [Q E H C A D]
time 254475ms: Process F completed a CPU burst; 55 bursts to go [Q E H C A D]
time 254475ms: Process F switching out of CPU; will block on I/O until time 255430ms [Q E H C A D]
time 254479ms: Process E started using the CPU for 654ms burst [Q H C A D]
time 255133ms: Process E completed a CPU burst; 42 bursts to go [Q H C A D]
time 255133ms: Process E switching out of CPU; will block on I/O until time 256019ms [Q H C A D]
time 255137ms: Process H started using the CPU for 1685ms burst [Q C A D]
time 255430ms: Process F completed I/O; added to ready queue [Q C A D F]
time 256019ms: Process E completed I/O; added to ready queue [Q C A D F E]
time 256822ms: Process H completed a CPU burst; 2 bursts to go [Q C A D F E]
time 256822ms: Process H switching out of CPU; will block on I/O until time 257098ms [Q C A D F E]
time 256826ms: Process C started using the CPU for 37ms burst [Q A D F E]
time 256863ms: Process C completed a CPU burst; 48 bursts to go [Q A D F E]
time 256863ms: Process C switching out of CPU; will block on I/O until time 258511ms [Q A D F E]
time 256867ms: Process A started using the CPU for 469ms burst [Q D F E]
time 257098ms: Process H completed I/O; added to ready queue [Q D F E H]
time 257336ms: Process A completed a CPU burst; 38 bursts to go [Q D F E H]
time 257336ms: Process A switching out of CPU; will block on I/O until time 257554ms [Q D F E H]
time 257340ms: Process D started using the CPU for 4ms burst [Q F E H]
time 257344ms: Process D completed a CPU burst; 14 bursts to go [Q F E H]
time 257344ms: Process D switching out of CPU; will block on I/O until time 258403ms [Q F E H]
time 257348ms: Process F started using the CPU for 745ms burst [Q E H]
time 257554ms: Process A completed I/O; added to ready queue [Q E H A]
time 258093ms: Process F completed a CPU burst; 54 bursts to go [Q E H A]
time 258093ms: Process F switching out of CPU; will block on I/O until time 258154ms [Q E H A]
time 258097ms: Process E started using the CPU for 539ms burst [Q H A]
time 258154ms: Process F completed I/O; added to ready queue [Q H A F]
time 258403ms: Process D completed I/O; added to ready queue [Q H A F D]
time 258511ms: Process C completed I/O; added to ready queue [Q H A F D C]
time 258636ms: Process E completed a CPU burst; 41 bursts to go [Q H A F D C]
time 258636ms: Process E switching out of CPU; will block on I/O until time 260195ms [Q H A F D C]
time 258640ms: Process H started using the CPU for 401ms burst [Q A F D C]
time 259041ms: Process H completed a CPU burst; 1 burst to go [Q A F D C]
time 259041ms: Process H switching out of CPU; will block on I/O until time 259346ms [Q A F D C]
time 259045ms: Process A started using the CPU for 2254ms burst [Q F D C]
time 259346ms: Process H completed I/O; added to ready queue [Q F D C H]
time 260195ms: Process E completed I/O; added to ready queue [Q F D C H E]
time 261299ms: Process A completed a CPU burst; 37 bursts to go [Q F D C H E]
time 261299ms: Process A switching out of CPU; will block on I/O until time 262763ms [Q F D C H E]
time 261303ms: Process F started using the CPU for 1011ms burst [Q D C H E]
time 262314ms: Process F completed a CPU burst; 53 bursts to go [Q D C H E]
time 262314ms: Process F switching out of CPU; will block on I/O until time 262658ms [Q D C H E]
time 262318ms: Process D started using the CPU for 1008ms burst [Q C H E]
time 262658ms: Process F completed I/O; added to ready queue [Q C H E F]
time 262763ms: Process A completed I/O; added to ready queue [Q C H E F A]
time 263326ms: Process D completed a CPU burst; 13 bursts to go [Q C H E F A]
time 263326ms: Process D switching out of CPU; will block on I/O until time 263476ms [Q C H E F A]
time 263330ms: Process C started using the CPU for 311ms burst [Q H E F A]
time 263476ms: Process D completed I/O; added to ready queue [Q H E F A D]
time 263641ms: Process C completed a CPU burst; 47 bursts to go [Q H E F A D]
time 263641ms: Process C switching out of CPU; will block on I/O until time 264288ms [Q H E F A D]
time 263645ms: Process H started using the CPU for 1387ms burst [Q E F A D]
time 264288ms: Process C completed I/O; added to ready queue [Q E F A D C]
time 265032ms: Process H terminated [Q E F A D C]
time 265036ms: Process E started using the CPU for 1801ms burst [Q F A D C]
time 266837ms: Process E completed a CPU burst; 40 bursts to go [Q F A D C]
time 266837ms: Process E switching out of CPU; will block on I/O until time 269459ms [Q F A D C]
time 266841ms: Process F started using the CPU for 1577ms burst [Q A D C]
time 268418ms: Process F completed a CPU burst; 52 bursts to go [Q A D C]
time 268418ms: Process F switching out of CPU; will block on I/O until time 268720ms [Q A D C]
time 268422ms: Process A started using the CPU for 1566ms burst [Q D C]
time 268720ms: Process F completed I/O; added to ready queue [Q D C F]
time 269459ms: Process E completed I/O; added to ready queue [Q D C F E]
time 269988ms: Process A completed a CPU burst; 36 bursts to go [Q D C F E]
time 269988ms: Process A switching out of CPU; will block on I/O until time 270907ms [Q D C F E]
time 269992ms: Process D started using the CPU for 802ms burst [Q C F E]
time 270794ms: Process D completed a CPU burst; 12 bursts to go [Q C F E]
time 270794ms: Process D switching out of CPU; will block on I/O until time 271551ms [Q C F E]
time 270798ms: Process C started using the CPU for 601ms burst [Q F E]
time 270907ms: Process A completed I/O; added to ready queue [Q F E A]
time 271399ms: Process C completed a CPU burst; 46 bursts to go [Q F E A]
time 271399ms: Process C switching out of CPU; will block on I/O until time 272036ms [Q F E A]
time 271403ms: Process F started using the CPU for 70ms burst [Q E A]
time 271473ms: Process F completed a CPU burst; 51 bursts to go [Q E A]
time 271473ms: Process F switching out of CPU; will block on I/O until time 271955ms [Q E A]
time 271477ms: Process E started using the CPU for 343ms burst [Q A]
time 271551ms: Process D completed I/O; added to ready queue [Q A D]
time 271820ms: Process E completed a CPU burst; 39 bursts to go [Q A D]
time 271820ms: Process E switching out of CPU; will block on I/O until time 272133ms [Q A D]
time 271824ms: Process A started using the CPU for 73ms burst [Q D]
time 271897ms: Process A completed a CPU burst; 35 bursts to go [Q D]
time 271897ms: Process A switching out of CPU; will block on I/O until time 271920ms [Q D]
time 271901ms: Process D started using the CPU for 1876ms burst [Q <empty>]
time 271920ms: Process A completed I/O; added to ready queue [Q A]
time 271955ms: Process F completed I/O; added to ready queue [Q A F]
time 272036ms: Process C completed I/O; added to ready queue [Q A F C]
time 272133ms: Process E completed I/O; added to ready queue [Q A F C E]
time 273777ms: Process D completed a CPU burst; 11 bursts to go [Q A F C E]
time 273777ms: Process D switching out of CPU; will block on I/O until time 273976ms [Q A F C E]
time 273781ms: Process A started using the CPU for 274ms burst [Q F C E]
time 273976ms: Process D completed I/O; added to ready queue [Q F C E D]
time 274055ms: Process A completed a CPU burst; 34 bursts to go [Q F C E D]
time 274055ms: Process A switching out of CPU; will block on I/O until time 274705ms [Q F C E D]
time 274059ms: Process F started using the CPU for 755ms burst [Q C E D]
time 274705ms: Process A completed I/O; added to ready queue [Q C E D A]
time 274814ms: Process F completed a CPU burst; 50 bursts to go [Q C E D A]
time 274814ms: Process F switching out of CPU; will block on I/O until time 275114ms [Q C E D A]
time 274818ms: Process C started using the CPU for 3837ms burst [Q E D A]
time 275114ms: Process F completed I/O; added to ready queue [Q E D A F]
time 278655ms: Process C completed a CPU burst; 45 bursts to go [Q E D A F]
time 278655ms: Process C switching out of CPU; will block on I/O until time 279837ms [Q E D A F]
time 278659ms: Process E started using the CPU for 141ms burst [Q D A F]
time 278800ms: Process E completed a CPU burst; 38 bursts to go [Q D A F]
time 278800ms: Process E switching out of CPU; will block on I/O until time 281123ms [Q D A F]
time 278804ms: Process D started using the CPU for 1007ms burst [Q A F]
time 279811ms: Process D completed a CPU burst; 10 bursts to go [Q A F]
time 279811ms: Process D switching out of CPU; will block on I/O until time 281010ms [Q A F]
time 279815ms: Process A started using the CPU for 453ms burst [Q F]
time 279837ms: Process C completed I/O; added to ready queue [Q F C]
time 280268ms: Process A completed a CPU burst; 33 bursts to go [Q F C]
time 280268ms: Process A switching out of CPU; will block on I/O until time 280441ms [Q F C]
time 280272ms: Process F started using the CPU for 3504ms burst [Q C]
time 280441ms: Process A completed I/O; added to ready queue [Q C A]
time 281010ms: Process D completed I/O; added to ready queue [Q C A D]
time 281123ms: Process E completed I/O; added to ready queue [Q C A D E]
time 283776ms: Process F completed a CPU burst; 49 bursts to go [Q C A D E]
time 283776ms: Process F switching out of CPU; will block on I/O until time 285213ms [Q C A D E]
time 283780ms: Process C started using the CPU for 25ms burst [Q A D E]
time 283805ms: Process C completed a CPU burst; 44 bursts to go [Q A D E]
time 283805ms: Process C switching out of CPU; will block on I/O until time 284433ms [Q A D E]
time 283809ms: Process A started using the CPU for 26ms burst [Q D E]
time 283835ms: Process A completed a CPU burst; 32 bursts to go [Q D E]
time 283835ms: Process A switching out of CPU; will block on I/O until time 284243ms [Q D E]
time 283839ms: Process D started using the CPU for 2955ms burst [Q E]
time 284243ms: Process A completed I/O; added to ready queue [Q E A]
time 284433ms: Process C completed I/O; added to ready queue [Q E A C]
time 285213ms: Process F completed I/O; added to ready queue [Q E A C F]
time 286794ms: Process D completed a CPU burst; 9 bursts to go [Q E A C F]
time 286794ms: Process D switching out of CPU; will block on I/O until time 288445ms [Q E A C F]
time 286798ms: Process E started using the CPU for 616ms burst [Q A C F]
time 287414ms: Process E completed a CPU burst; 37 bursts to go [Q A C F]
time 287414ms: Process E switching out of CPU; will block on I/O until time 287857ms [Q A C F]
time 287418ms: Process A started using the CPU for 1006ms burst [Q C F]
time 287857ms: Process E completed I/O; added to ready queue [Q C F E]
time 288424ms: Process A completed a CPU burst; 31 bursts to go [Q C F E]
time 288424ms: Process A switching out of CPU; will block on I/O until time 288904ms [Q C F E]
time 288428ms: Process C started using the CPU for 104ms burst [Q F E]
time 288445ms: Process D completed I/O; added to ready queue [Q F E D]
time 288532ms: Process C completed a CPU burst; 43 bursts to go [Q F E D]
time 288532ms: Process C switching out of CPU; will block on I/O until time 289052ms [Q F E D]
time 288536ms: Process F started using the CPU for 484ms burst [Q E D]
time 288904ms: Process A completed I/O; added to ready queue [Q E D A]
time 289020ms: Process F completed a CPU burst; 48 bursts to go [Q E D A]
time 289020ms: Process F switching out of CPU; will block on I/O until time 289107ms [Q E D A]
time 289024ms: Process E started using the CPU for 1898ms burst [Q D A]
time 289052ms: Process C completed I/O; added to ready queue [Q D A C]
time 289107ms: Process F completed I/O; added to ready queue [Q D A C F]
time 290922ms: Process E completed a CPU burst; 36 bursts to go [Q D A C F]
time 290922ms: Process E switching out of CPU; will block on I/O until time 290953ms [Q D A C F]
time 290926ms: Process D started using the CPU for 11ms burst [Q A C F]
time 290937ms: Process D completed a CPU burst; 8 bursts to go [Q A C F]
time 290937ms: Process D switching out of CPU; will block on I/O until time 292385ms [Q A C F]
time 290941ms: Process A started using the CPU for 2185ms burst [Q C F]
time 290953ms: Process E completed I/O; added to ready queue [Q C F E]
time 292385ms: Process D completed I/O; added to ready queue [Q C F E D]
time 293126ms: Process A completed a CPU burst; 30 bursts to go [Q C F E D]
time 293126ms: Process A switching out of CPU; will block on I/O until time 293259ms [Q C F E D]
time 293130ms: Process C started using the CPU for 538ms burst [Q F E D]
time 293259ms: Process A completed I/O; added to ready queue [Q F E D A]
time 293668ms: Process C completed a CPU burst; 42 bursts to go [Q F E D A]
