Process A [NEW] (arrival time 9 ms) 16 CPU bursts
Process B [NEW] (arrival time 18 ms) 21 CPU bursts
time 0ms: Simulator started for FCFS [Q <empty>]
time 9ms: Process A arrived; added to ready queue [Q A]
time 11ms: Process A started using the CPU for 56ms burst [Q <empty>]
time 18ms: Process B arrived; added to ready queue [Q B]
time 67ms: Process A completed a CPU burst; 15 bursts to go [Q B]
time 67ms: Process A switching out of CPU; will block on I/O until time 92ms [Q B]
time 71ms: Process B started using the CPU for 60ms burst [Q <empty>]
time 92ms: Process A completed I/O; added to ready queue [Q A]
time 131ms: Process B completed a CPU burst; 20 bursts to go [Q A]
time 131ms: Process B switching out of CPU; will block on I/O until time 286ms [Q A]
time 135ms: Process A started using the CPU for 39ms burst [Q <empty>]
time 174ms: Process A completed a CPU burst; 14 bursts to go [Q <empty>]
time 174ms: Process A switching out of CPU; will block on I/O until time 226ms [Q <empty>]
time 226ms: Process A completed I/O; added to ready queue [Q A]
time 228ms: Process A started using the CPU for 47ms burst [Q <empty>]
time 275ms: Process A completed a CPU burst; 13 bursts to go [Q <empty>]
time 275ms: Process A switching out of CPU; will block on I/O until time 279ms [Q <empty>]
time 279ms: Process A completed I/O; added to ready queue [Q A]
time 281ms: Process A started using the CPU for 137ms burst [Q <empty>]
time 286ms: Process B completed I/O; added to ready queue [Q B]
time 418ms: Process A completed a CPU burst; 12 bursts to go [Q B]
time 418ms: Process A switching out of CPU; will block on I/O until time 444ms [Q B]
time 422ms: Process B started using the CPU for 64ms burst [Q <empty>]
time 444ms: Process A completed I/O; added to ready queue [Q A]
time 486ms: Process B completed a CPU burst; 19 bursts to go [Q A]
time 486ms: Process B switching out of CPU; will block on I/O until time 503ms [Q A]
time 490ms: Process A started using the CPU for 68ms burst [Q <empty>]
time 503ms: Process B completed I/O; added to ready queue [Q B]
time 558ms: Process A completed a CPU burst; 11 bursts to go [Q B]
time 558ms: Process A switching out of CPU; will block on I/O until time 624ms [Q B]
time 562ms: Process B started using the CPU for 113ms burst [Q <empty>]
time 624ms: Process A completed I/O; added to ready queue [Q A]
time 675ms: Process B completed a CPU burst; 18 bursts to go [Q A]
time 675ms: Process B switching out of CPU; will block on I/O until time 693ms [Q A]
time 679ms: Process A started using the CPU for 11ms burst [Q <empty>]
time 690ms: Process A completed a CPU burst; 10 bursts to go [Q <empty>]
time 690ms: Process A switching out of CPU; will block on I/O until time 854ms [Q <empty>]
time 854ms: Process A completed I/O; added to ready queue [Q A]
time 856ms: Process A started using the CPU for 24ms burst [Q <empty>]
time 880ms: Process A completed a CPU burst; 9 bursts to go [Q <empty>]
time 880ms: Process A switching out of CPU; will block on I/O until time 999ms [Q <empty>]
time 999ms: Process A completed I/O; added to ready queue [Q A]
time 1001ms: Process A started using the CPU for 76ms burst [Q <empty>]
time 1077ms: Process A completed a CPU burst; 8 bursts to go [Q <empty>]
time 1077ms: Process A switching out of CPU; will block on I/O until time 1107ms [Q <empty>]
time 1107ms: Process A completed I/O; added to ready queue [Q A]
time 1109ms: Process A started using the CPU for 122ms burst [Q <empty>]
time 1231ms: Process A completed a CPU burst; 7 bursts to go [Q <empty>]
time 1231ms: Process A switching out of CPU; will block on I/O until time 1266ms [Q <empty>]
time 1266ms: Process A completed I/O; added to ready queue [Q A]
time 1268ms: Process A started using the CPU for 9ms burst [Q <empty>]
time 1277ms: Process A completed a CPU burst; 6 bursts to go [Q <empty>]
time 1277ms: Process A switching out of CPU; will block on I/O until time 1347ms [Q <empty>]
time 1347ms: Process A completed I/O; added to ready queue [Q A]
time 1349ms: Process A started using the CPU for 62ms burst [Q <empty>]
time 1411ms: Process A completed a CPU burst; 5 bursts to go [Q <empty>]
time 1411ms: Process A switching out of CPU; will block on I/O until time 1490ms [Q <empty>]
time 1490ms: Process A completed I/O; added to ready queue [Q A]
time 1492ms: Process A started using the CPU for 200ms burst [Q <empty>]
time 1692ms: Process A completed a CPU burst; 4 bursts to go [Q <empty>]
time 1692ms: Process A switching out of CPU; will block on I/O until time 1705ms [Q <empty>]
time 1705ms: Process A completed I/O; added to ready queue [Q A]
time 1707ms: Process A started using the CPU for 197ms burst [Q <empty>]
time 1904ms: Process A completed a CPU burst; 3 bursts to go [Q <empty>]
time 1904ms: Process A switching out of CPU; will block on I/O until time 2062ms [Q <empty>]
time 2062ms: Process A completed I/O; added to ready queue [Q A]
time 2064ms: Process A started using the CPU for 106ms burst [Q <empty>]
time 2170ms: Process A completed a CPU burst; 2 bursts to go [Q <empty>]
time 2170ms: Process A switching out of CPU; will block on I/O until time 2285ms [Q <empty>]
time 2285ms: Process A completed I/O; added to ready queue [Q A]
time 2287ms: Process A started using the CPU for 198ms burst [Q <empty>]
time 2485ms: Process A completed a CPU burst; 1 burst to go [Q <empty>]
time 2485ms: Process A switching out of CPU; will block on I/O until time 2649ms [Q <empty>]
time 2649ms: Process A completed I/O; added to ready queue [Q A]
time 2651ms: Process A started using the CPU for 208ms burst [Q <empty>]
time 2859ms: Process A terminated [Q <empty>]
